Workbook
Name 切片器_机种: #N/A
Name 切片器_客户_發生處: #N/A
Name 切片器_月份: #N/A

Sheet 汇总
C2: 2026年客诉看板
D4: 客诉件数 | F4: =D7+G7+K7 -> 0 | H4: 4月 | I4: 客诉件数 | K4: =COUNTIF('客诉跟进表 '!A:A,H4) -> 0
G5: 件 | L5: 件
C7: Open | D7: =COUNTIF('客诉跟进表 '!Y:Y,"Open") -> 0 | E7: 件 | F7: On-going | G7: =COUNTIF('客诉跟进表 '!Y:Y,"On-going") -> 0 | H7: 件 | J7: Closed | K7: =COUNTIF('客诉跟进表 '!Y:Y,"Closed") -> 0 | L7: 件

Sheet 客诉跟进表 
A1: 月份 | B1: 产品线 | C1: 序号 | D1: 问题归类 | E1: 不良类型归类 | F1: 投诉日期 | G1: 系列 | H1: 详细机种 | I1: 生产地 | J1: 客户/發生處 | K1: 投诉内容 | L1: 不良率 | M1: 暂定对策 | N1: 不良属性 | O1: 责任部门 | P1: 责任跟踪者 | Q1: 结案日期 | R1: 结案天数 | S1: 结案状况（Y/N） | T1: 不良原因 | U1: 改善对策(恒久对策） | V1: 内部未结案待跟进事项 | W1: 结案后稽核事项（25/11/6开始） | X1: 原因归类 | Y1: 结案状态 | Z1: 延期天数 | AA1: 模块

Sheet 月度推移图
B3: 月度 | C3: closed | D3: on-going | E3: open | F3: 总件数 | G3: 结案率 | H3: 结案平均天数 | I3: 总结案天数
B4: 1月 | C4: =SUMPRODUCT(('客诉跟进表 '!$A$2:$A$613=月度推移图!B4)*('客诉跟进表 '!$Y$2:$Y$613=$C$3)) -> 0 | D4: =SUMPRODUCT(('客诉跟进表 '!$A$2:$A$613=月度推移图!B4)*('客诉跟进表 '!$Y$2:$Y$613=$D$3)) -> 0 | E4: =SUMPRODUCT(('客诉跟进表 '!$A$2:$A$613=月度推移图!B4)*('客诉跟进表 '!$Y$2:$Y$613=$E$3)) -> 0 | F4: =SUM(C4:E4) -> 0 | G4: =C4/F4 -> #DIV/0! | H4: =IF(I4=0,#N/A,I4/C4) -> #N/A | I4: =SUMIF('客诉跟进表 '!$A$2:$A$406,月度推移图!B4,'客诉跟进表 '!$R$2:$R$406) -> 0
B5: 2月 | C5: =SUMPRODUCT(('客诉跟进表 '!$A$2:$A$613=月度推移图!B5)*('客诉跟进表 '!$Y$2:$Y$613=$C$3)) -> 0 | D5: =SUMPRODUCT(('客诉跟进表 '!$A$2:$A$613=月度推移图!B5)*('客诉跟进表 '!$Y$2:$Y$613=$D$3)) -> 0 | E5: =SUMPRODUCT(('客诉跟进表 '!$A$2:$A$613=月度推移图!B5)*('客诉跟进表 '!$Y$2:$Y$613=$E$3)) -> 0 | F5: =SUM(C5:E5) -> 0 | G5: =C5/F5 -> #DIV/0! | H5: =IF(I5=0,#N/A,I5/C5) -> #N/A | I5: =SUMIF('客诉跟进表 '!$A$2:$A$406,月度推移图!B5,'客诉跟进表 '!$R$2:$R$406) -> 0
B6: 3月 | C6: =SUMPRODUCT(('客诉跟进表 '!$A$2:$A$613=月度推移图!B6)*('客诉跟进表 '!$Y$2:$Y$613=$C$3)) -> 0 | D6: =SUMPRODUCT(('客诉跟进表 '!$A$2:$A$613=月度推移图!B6)*('客诉跟进表 '!$Y$2:$Y$613=$D$3)) -> 0 | E6: =SUMPRODUCT(('客诉跟进表 '!$A$2:$A$613=月度推移图!B6)*('客诉跟进表 '!$Y$2:$Y$613=$E$3)) -> 0 | F6: =SUM(C6:E6) -> 0 | G6: =C6/F6 -> #DIV/0! | H6: =IF(I6=0,#N/A,I6/C6) -> #N/A | I6: =SUMIF('客诉跟进表 '!$A$2:$A$406,月度推移图!B6,'客诉跟进表 '!$R$2:$R$406) -> 0
B7: 4月 | C7: =SUMPRODUCT(('客诉跟进表 '!$A$2:$A$613=月度推移图!B7)*('客诉跟进表 '!$Y$2:$Y$613=$C$3)) -> 0 | D7: =SUMPRODUCT(('客诉跟进表 '!$A$2:$A$613=月度推移图!B7)*('客诉跟进表 '!$Y$2:$Y$613=$D$3)) -> 0 | E7: =SUMPRODUCT(('客诉跟进表 '!$A$2:$A$613=月度推移图!B7)*('客诉跟进表 '!$Y$2:$Y$613=$E$3)) -> 0 | F7: =SUM(C7:E7) -> 0 | G7: =C7/F7 -> #DIV/0! | H7: =IF(I7=0,#N/A,I7/C7) -> #N/A | I7: =SUMIF('客诉跟进表 '!$A$2:$A$406,月度推移图!B7,'客诉跟进表 '!$R$2:$R$406) -> 0
B8: 5月 | C8: =SUMPRODUCT(('客诉跟进表 '!$A$2:$A$613=月度推移图!B8)*('客诉跟进表 '!$Y$2:$Y$613=$C$3)) -> 0 | D8: =SUMPRODUCT(('客诉跟进表 '!$A$2:$A$613=月度推移图!B8)*('客诉跟进表 '!$Y$2:$Y$613=$D$3)) -> 0 | E8: =SUMPRODUCT(('客诉跟进表 '!$A$2:$A$613=月度推移图!B8)*('客诉跟进表 '!$Y$2:$Y$613=$E$3)) -> 0 | F8: =SUM(C8:E8) -> 0 | G8: =C8/F8 -> #DIV/0! | H8: =IF(I8=0,#N/A,I8/C8) -> #N/A | I8: =SUMIF('客诉跟进表 '!$A$2:$A$406,月度推移图!B8,'客诉跟进表 '!$R$2:$R$406) -> 0
B9: 6月 | C9: =SUMPRODUCT(('客诉跟进表 '!$A$2:$A$613=月度推移图!B9)*('客诉跟进表 '!$Y$2:$Y$613=$C$3)) -> 0 | D9: =SUMPRODUCT(('客诉跟进表 '!$A$2:$A$613=月度推移图!B9)*('客诉跟进表 '!$Y$2:$Y$613=$D$3)) -> 0 | E9: =SUMPRODUCT(('客诉跟进表 '!$A$2:$A$613=月度推移图!B9)*('客诉跟进表 '!$Y$2:$Y$613=$E$3)) -> 0 | F9: =SUM(C9:E9) -> 0 | G9: =C9/F9 -> #DIV/0! | H9: =IF(I9=0,#N/A,I9/C9) -> #N/A | I9: =SUMIF('客诉跟进表 '!$A$2:$A$406,月度推移图!B9,'客诉跟进表 '!$R$2:$R$406) -> 0
B10: 7月 | C10: =SUMPRODUCT(('客诉跟进表 '!$A$2:$A$613=月度推移图!B10)*('客诉跟进表 '!$Y$2:$Y$613=$C$3)) -> 0 | D10: =SUMPRODUCT(('客诉跟进表 '!$A$2:$A$613=月度推移图!B10)*('客诉跟进表 '!$Y$2:$Y$613=$D$3)) -> 0 | E10: =SUMPRODUCT(('客诉跟进表 '!$A$2:$A$613=月度推移图!B10)*('客诉跟进表 '!$Y$2:$Y$613=$E$3)) -> 0 | F10: =SUM(C10:E10) -> 0 | G10: =C10/F10 -> #DIV/0! | H10: =IF(I10=0,#N/A,I10/C10) -> #N/A | I10: =SUMIF('客诉跟进表 '!$A$2:$A$406,月度推移图!B10,'客诉跟进表 '!$R$2:$R$406) -> 0
B11: 8月 | C11: =SUMPRODUCT(('客诉跟进表 '!$A$2:$A$613=月度推移图!B11)*('客诉跟进表 '!$Y$2:$Y$613=$C$3)) -> 0 | D11: =SUMPRODUCT(('客诉跟进表 '!$A$2:$A$613=月度推移图!B11)*('客诉跟进表 '!$Y$2:$Y$613=$D$3)) -> 0 | E11: =SUMPRODUCT(('客诉跟进表 '!$A$2:$A$613=月度推移图!B11)*('客诉跟进表 '!$Y$2:$Y$613=$E$3)) -> 0 | F11: =SUM(C11:E11) -> 0 | G11: =C11/F11 -> #DIV/0! | H11: =IF(I11=0,#N/A,I11/C11) -> #N/A | I11: =SUMIF('客诉跟进表 '!$A$2:$A$406,月度推移图!B11,'客诉跟进表 '!$R$2:$R$406) -> 0
B12: 9月 | C12: =SUMPRODUCT(('客诉跟进表 '!$A$2:$A$613=月度推移图!B12)*('客诉跟进表 '!$Y$2:$Y$613=$C$3)) -> 0 | D12: =SUMPRODUCT(('客诉跟进表 '!$A$2:$A$613=月度推移图!B12)*('客诉跟进表 '!$Y$2:$Y$613=$D$3)) -> 0 | E12: =SUMPRODUCT(('客诉跟进表 '!$A$2:$A$613=月度推移图!B12)*('客诉跟进表 '!$Y$2:$Y$613=$E$3)) -> 0 | F12: =SUM(C12:E12) -> 0 | G12: =C12/F12 -> #DIV/0! | H12: =IF(I12=0,#N/A,I12/C12) -> #N/A | I12: =SUMIF('客诉跟进表 '!$A$2:$A$406,月度推移图!B12,'客诉跟进表 '!$R$2:$R$406) -> 0
B13: 10月 | C13: =SUMPRODUCT(('客诉跟进表 '!$A$2:$A$613=月度推移图!B13)*('客诉跟进表 '!$Y$2:$Y$613=$C$3)) -> 0 | D13: =SUMPRODUCT(('客诉跟进表 '!$A$2:$A$613=月度推移图!B13)*('客诉跟进表 '!$Y$2:$Y$613=$D$3)) -> 0 | E13: =SUMPRODUCT(('客诉跟进表 '!$A$2:$A$613=月度推移图!B13)*('客诉跟进表 '!$Y$2:$Y$613=$E$3)) -> 0 | F13: =SUM(C13:E13) -> 0 | G13: =C13/F13 -> #DIV/0! | H13: =IF(I13=0,#N/A,I13/C13) -> #N/A | I13: =SUMIF('客诉跟进表 '!$A$2:$A$406,月度推移图!B13,'客诉跟进表 '!$R$2:$R$406) -> 0
B14: 11月 | C14: =SUMPRODUCT(('客诉跟进表 '!$A$2:$A$613=月度推移图!B14)*('客诉跟进表 '!$Y$2:$Y$613=$C$3)) -> 0 | D14: =SUMPRODUCT(('客诉跟进表 '!$A$2:$A$613=月度推移图!B14)*('客诉跟进表 '!$Y$2:$Y$613=$D$3)) -> 0 | E14: =SUMPRODUCT(('客诉跟进表 '!$A$2:$A$613=月度推移图!B14)*('客诉跟进表 '!$Y$2:$Y$613=$E$3)) -> 0 | F14: =SUM(C14:E14) -> 0 | G14: =C14/F14 -> #DIV/0! | H14: =IF(I14=0,#N/A,I14/C14) -> #N/A | I14: =SUMIF('客诉跟进表 '!$A$2:$A$406,月度推移图!B14,'客诉跟进表 '!$R$2:$R$406) -> 0
B15: 12月 | C15: =SUMPRODUCT(('客诉跟进表 '!$A$2:$A$613=月度推移图!B15)*('客诉跟进表 '!$Y$2:$Y$613=$C$3)) -> 0 | D15: =SUMPRODUCT(('客诉跟进表 '!$A$2:$A$613=月度推移图!B15)*('客诉跟进表 '!$Y$2:$Y$613=$D$3)) -> 0 | E15: =SUMPRODUCT(('客诉跟进表 '!$A$2:$A$613=月度推移图!B15)*('客诉跟进表 '!$Y$2:$Y$613=$E$3)) -> 0 | F15: =SUM(C15:E15) -> 0 | G15: =IF(F15=0,#N/A,C15/F15) -> #N/A | H15: =IF(I15=0,#N/A,I15/C15) -> #N/A | I15: =SUMIF('客诉跟进表 '!$A$2:$A$406,月度推移图!B15,'客诉跟进表 '!$R$2:$R$406) -> 0
B16: 合计 | C16: =SUM(C4:C15) -> 0 | D16: =SUM(D4:D15) -> 0 | E16: =SUM(E4:E15) -> 0 | F16: =SUM(F4:F15) -> 0 | G16: =IF(F16=0,#N/A,C16/F16) -> #N/A | H16: =IF(I16=0,#N/A,I16/C16) -> #N/A | I16: =SUM(I4:I15) -> 0

Sheet 月度跟进情况
B2: 各担当客诉结案状况
B4: 客户担当 | C4: 客诉总件数 | D4: 结案件数 | E4: 累计结案率
C6: =COUNTIF('客诉跟进表 '!$P:P,月度跟进情况!B6) -> 0 | D6: =SUMPRODUCT(('客诉跟进表 '!$P:P=月度跟进情况!B6)*('客诉跟进表 '!$Y:Y=汇总!$J$7)) -> 0 | E6: =IF(C6=0,#N/A,D6/C6) -> #N/A
C7: =COUNTIF('客诉跟进表 '!$P:P,月度跟进情况!B7) -> 0 | D7: =SUMPRODUCT(('客诉跟进表 '!$P:P=月度跟进情况!B7)*('客诉跟进表 '!$Y:Y=汇总!$J$7)) -> 0 | E7: =IF(C7=0,#N/A,D7/C7) -> #N/A
C8: =COUNTIF('客诉跟进表 '!$P:P,月度跟进情况!B8) -> 0 | D8: =SUMPRODUCT(('客诉跟进表 '!$P:P=月度跟进情况!B8)*('客诉跟进表 '!$Y:Y=汇总!$J$7)) -> 0 | E8: =IF(C8=0,#N/A,D8/C8) -> #N/A
C9: =COUNTIF('客诉跟进表 '!$P:P,月度跟进情况!B9) -> 0 | D9: =SUMPRODUCT(('客诉跟进表 '!$P:P=月度跟进情况!B9)*('客诉跟进表 '!$Y:Y=汇总!$J$7)) -> 0 | E9: =IF(C9=0,#N/A,D9/C9) -> #N/A
C10: =COUNTIF('客诉跟进表 '!$P:P,月度跟进情况!B10) -> 0 | D10: =SUMPRODUCT(('客诉跟进表 '!$P:P=月度跟进情况!B10)*('客诉跟进表 '!$Y:Y=汇总!$J$7)) -> 0 | E10: =IF(C10=0,#N/A,D10/C10) -> #N/A
C11: =COUNTIF('客诉跟进表 '!$P:P,月度跟进情况!B11) -> 0 | D11: =SUMPRODUCT(('客诉跟进表 '!$P:P=月度跟进情况!B11)*('客诉跟进表 '!$Y:Y=汇总!$J$7)) -> 0 | E11: =IF(C11=0,#N/A,D11/C11) -> #N/A
C12: =COUNTIF('客诉跟进表 '!$P:P,月度跟进情况!B12) -> 0 | D12: =SUMPRODUCT(('客诉跟进表 '!$P:P=月度跟进情况!B12)*('客诉跟进表 '!$Y:Y=汇总!$J$7)) -> 0 | E12: =IF(C12=0,#N/A,D12/C12) -> #N/A
C13: =COUNTIF('客诉跟进表 '!$P:P,月度跟进情况!B13) -> 0 | D13: =SUMPRODUCT(('客诉跟进表 '!$P:P=月度跟进情况!B13)*('客诉跟进表 '!$Y:Y=汇总!$J$7)) -> 0 | E13: =IF(C13=0,#N/A,D13/C13) -> #N/A
C14: =COUNTIF('客诉跟进表 '!$P:P,月度跟进情况!B14) -> 0 | D14: =SUMPRODUCT(('客诉跟进表 '!$P:P=月度跟进情况!B14)*('客诉跟进表 '!$Y:Y=汇总!$J$7)) -> 0 | E14: =IF(C14=0,#N/A,D14/C14) -> #N/A
C15: =COUNTIF('客诉跟进表 '!$P:P,月度跟进情况!B15) -> 0 | D15: =SUMPRODUCT(('客诉跟进表 '!$P:P=月度跟进情况!B15)*('客诉跟进表 '!$Y:Y=汇总!$J$7)) -> 0 | E15: =IF(C15=0,#N/A,D15/C15) -> #N/A
C16: =COUNTIF('客诉跟进表 '!$P:P,月度跟进情况!B16) -> 0 | D16: =SUMPRODUCT(('客诉跟进表 '!$P:P=月度跟进情况!B16)*('客诉跟进表 '!$Y:Y=汇总!$J$7)) -> 0 | E16: =IF(C16=0,#N/A,D16/C16) -> #N/A
C17: =COUNTIF('客诉跟进表 '!$P:P,月度跟进情况!B17) -> 0 | D17: =SUMPRODUCT(('客诉跟进表 '!$P:P=月度跟进情况!B17)*('客诉跟进表 '!$Y:Y=汇总!$J$7)) -> 0 | E17: =IF(C17=0,#N/A,D17/C17) -> #N/A
... C21: =COUNTIF('客诉跟进表 '!$P:P,月度跟进情况!B21) -> 0 | D21: =SUMPRODUCT(('客诉跟进表 '!$P:P=月度跟进情况!B21)*('客诉跟进表 '!$Y:Y=汇总!$J$7)) -> 0 | E21: =IF(C21=0,#N/A,D21/C21) -> #N/A
B22: 合计 | C22: =SUM(C6:C21) -> 0 | D22: =SUM(D6:D21) -> 0 | E22: =IF(C22=0,#N/A,D22/C22) -> #N/A
B42: 月份 | C42: 客诉总件数 | D42: 结案件数 | E42: 累计结案率
B44: 1月 | C44: =COUNTIF('客诉跟进表 '!$A:A,月度跟进情况!B44) -> 0 | D44: =SUMPRODUCT(('客诉跟进表 '!$A:A=月度跟进情况!B44)*('客诉跟进表 '!$Y:Y=汇总!$J$7)) -> 0 | E44: =IF(C44=0,#N/A,D44/C44) -> #N/A
B45: 2月 | C45: =COUNTIF('客诉跟进表 '!$A:A,月度跟进情况!B45) -> 0 | D45: =SUMPRODUCT(('客诉跟进表 '!$A:A=月度跟进情况!B45)*('客诉跟进表 '!$Y:Y=汇总!$J$7)) -> 0 | E45: =IF(C45=0,#N/A,D45/C45) -> #N/A
B46: 3月 | C46: =COUNTIF('客诉跟进表 '!$A:A,月度跟进情况!B46) -> 0 | D46: =SUMPRODUCT(('客诉跟进表 '!$A:A=月度跟进情况!B46)*('客诉跟进表 '!$Y:Y=汇总!$J$7)) -> 0 | E46: =IF(C46=0,#N/A,D46/C46) -> #N/A
B47: 4月 | C47: =COUNTIF('客诉跟进表 '!$A:A,月度跟进情况!B47) -> 0 | D47: =SUMPRODUCT(('客诉跟进表 '!$A:A=月度跟进情况!B47)*('客诉跟进表 '!$Y:Y=汇总!$J$7)) -> 0 | E47: =IF(C47=0,#N/A,D47/C47) -> #N/A
B48: 5月 | C48: =COUNTIF('客诉跟进表 '!$A:A,月度跟进情况!B48) -> 0 | D48: =SUMPRODUCT(('客诉跟进表 '!$A:A=月度跟进情况!B48)*('客诉跟进表 '!$Y:Y=汇总!$J$7)) -> 0 | E48: =IF(C48=0,#N/A,D48/C48) -> #N/A
B49: 6月 | C49: =COUNTIF('客诉跟进表 '!$A:A,月度跟进情况!B49) -> 0 | D49: =SUMPRODUCT(('客诉跟进表 '!$A:A=月度跟进情况!B49)*('客诉跟进表 '!$Y:Y=汇总!$J$7)) -> 0 | E49: =IF(C49=0,#N/A,D49/C49) -> #N/A
B50: 7月 | C50: =COUNTIF('客诉跟进表 '!$A:A,月度跟进情况!B50) -> 0 | D50: =SUMPRODUCT(('客诉跟进表 '!$A:A=月度跟进情况!B50)*('客诉跟进表 '!$Y:Y=汇总!$J$7)) -> 0 | E50: =IF(C50=0,#N/A,D50/C50) -> #N/A
B51: 8月 | C51: =COUNTIF('客诉跟进表 '!$A:A,月度跟进情况!B51) -> 0 | D51: =SUMPRODUCT(('客诉跟进表 '!$A:A=月度跟进情况!B51)*('客诉跟进表 '!$Y:Y=汇总!$J$7)) -> 0 | E51: =IF(C51=0,#N/A,D51/C51) -> #N/A
B52: 9月 | C52: =COUNTIF('客诉跟进表 '!$A:A,月度跟进情况!B52) -> 0 | D52: =SUMPRODUCT(('客诉跟进表 '!$A:A=月度跟进情况!B52)*('客诉跟进表 '!$Y:Y=汇总!$J$7)) -> 0 | E52: =IF(C52=0,#N/A,D52/C52) -> #N/A
B53: 10月 | C53: =COUNTIF('客诉跟进表 '!$A:A,月度跟进情况!B53) -> 0 | D53: =SUMPRODUCT(('客诉跟进表 '!$A:A=月度跟进情况!B53)*('客诉跟进表 '!$Y:Y=汇总!$J$7)) -> 0 | E53: =IF(C53=0,#N/A,D53/C53) -> #N/A
B54: 11月 | C54: =COUNTIF('客诉跟进表 '!$A:A,月度跟进情况!B54) -> 0 | D54: =SUMPRODUCT(('客诉跟进表 '!$A:A=月度跟进情况!B54)*('客诉跟进表 '!$Y:Y=汇总!$J$7)) -> 0 | E54: =IF(C54=0,#N/A,D54/C54) -> #N/A
B55: 12月 | C55: =COUNTIF('客诉跟进表 '!$A:A,月度跟进情况!B55) -> 0 | D55: =SUMPRODUCT(('客诉跟进表 '!$A:A=月度跟进情况!B55)*('客诉跟进表 '!$Y:Y=汇总!$J$7)) -> 0 | E55: =IF(C55=0,#N/A,D55/C55) -> #N/A
B56: 合计 | C56: =SUM(C44:C55) -> 0 | D56: =SUM(D44:D55) -> 0
B59: 系列 | C59: 计数项:产品线
B60: AAA1 | C60: 13
B61: AAA2 | C61: 11
B62: AAA3 | C62: 10
B63: AAA4 | C63: 9
B64: AAA5 | C64: 9
B65: AAA6 | C65: 9
B66: AAA7 | C66: 7
B67: AAA8 | C67: 7
B68: AAA9 | C68: 7
...

Sheet 填写说明
A1: 月份 | B1: 类型 | C1: 序号 | D1: 问题归类 | E1: 不良原因归类 | F1: 投诉日期 | G1: 机种 | H1: 生产地 | I1: 客户/發生處 | J1: 投诉内容 | K1: 不良率 | L1: 暂定对策 | M1: 不良属性 | N1: 责任部门 | O1: 责任跟踪者 | P1: 结案日期 | Q1: 结案天数 | R1: 结案状况（Y/N） | S1: 不良原因 | T1: 改善对策(恒久对策） | U1: 结案状态
A2: 1月,2月… | B2: 填写镜头类型： 1.变焦 2.定焦 3.投影 4.部品 | C2: 1,2,3… | D2: 1.外观/脏污 2.作动不良 3.ICR异常 4.光圈异常 5.灯光异常 6.实拍异常 7.后焦异常 8.画面抖动 9.曲线不良 10.错漏混 11.其他 | E2: 1.标准问题 2.部品问题 3.人员作业问题 4.设计问题 5.制程问题 6.客户原因 7.低级错误 8.其他原因 9.待确认 | F2: 接到客户投诉/反馈问题当日 | G2: 社内料号 | H2: UN,BBH,DX… | I2: 如， DH产线 DH入料检 DH实验室 DH终端 | J2: 如， XX机种在XX条件下出现XX现象， 信息需包含不良品料号，数量，不良率，生产批次，生产线别/外协名称等（稍做整理） | K2: 格式： 不良数/投入数或检验数=不良率 | L2: 单品/组件/半成品/在制品/成品库存的处理方式，包括客户端、联合、供应商端 | M2: FA:单个不良品解析，不影响库存及在制 8D:不良品解析，影响库存及在制，需要封存或返工，罚款 | N2: 1.造成不良发生或流出的部门，不一定是镜头产线或外协 2.未有解析结果挂技术 3.未收到不良品挂品质 | O2: 负责根据处理的CQE人员 | P2: 与客户确认结案时间 | Q2: =结案日期-接到客户反馈当天 | R2: Y/N | S2: 概况性写 1.发生原因 2.流出原因 | T2: 对策项： 1.要有改善前/后的差异 2.对策落实的责任人及时间点 | U2: Open On-going Closed

Sheet 透视
A1: 月份 | B1: 7月 | D1: 月份 | E1: 7月 | G1: 月份 | H1: 7月
A2: 不良属性 | B2: 8D | D2: 不良属性 | E2: 8D | G2: 不良属性 | H2: 8D
D3: 结案状态 | E3: Closed | G3: 结案状态 | H3: On-going
A4: 责任跟踪者 | B4: 计数项:产品线
A5: 姚蓝政 | B5: 5 | D5: 责任跟踪者 | E5: 计数项:产品线 | G5: 责任跟踪者 | H5: 计数项:产品线
A6: 钟永佳 | B6: 4 | D6: 姚蓝政 | E6: 5 | G6: 钟永佳 | H6: 3
A7: 刘依林 | B7: 1 | D7: 钟永佳 | E7: 1 | G7: 刘依林 | H7: 1
A8: 黄乐贤 | B8: 1 | D8: 黄乐贤 | E8: 1 | G8: 总计 | H8: 4
A9: 总计 | B9: 11 | D9: 总计 | E9: 7
