Workbook
Name 责任单位: #REF!
Name 责任单位: #REF!

Sheet 类别定义  
A1: IPQC巡线问题点分类
A2: 类 别 | B2: 分 类 | C2: 定 义 | D2: 描 述 | E2: 责任单位
A3: 标准书管理类 | B3: SOP内容错误 | C3: 标准错误 | D3: 实际与描述不一致，且实际操作为正确的，手改SOP未配布 | E3: 技术单位
C4: 标准缺失 | D4: 需要管控项目未有体现，如漏UV、漏扭力、漏气压等 | E4: 技术单位
B5: SOP新旧共同使用 | C5: 新旧标准共存 | D5: 新版本配布旧版本未回收的 | E5: 使用单位
B6: 未配布SOP | C6: 标准改动未配布 | D6: 标准错误未在要求期配布正式版本 | E6: 技术单位
C7: 临时标准过期 | D7: 临时标准书、无sop仍在作业 | E7: 技术单位
C8: 标准书未受控 | D8: 标准书未受控进行使用 | E8: 使用单位
C9: 无标准书的作业 | D9: 有标准书未悬挂、悬挂位置错误、SOP遗失 | E9: 使用单位
A10: 不按标准作业 | B10: 未按标准作业 | C10: 不按标准要求使用工具 | D10: 工装治具、标准书要求使用静电风扇实际未使用 | E10: 使用单位
C11: 作业顺序和手法不合标准要求 | D11: 锁附顺序错误、标签/保护膜贴付未按样品及图示要求、部品失效脱落等 | E11: 使用单位
C12: 管控规格不符合标准要求 | D12: 作业气压、打压高度等不在标准规格内 | E12: 使用单位
C13: 不按标准要求进行记录 | D13: 实际有按要求执行，未进行记录。（抽检记录类）如：敲击、ICR作动、烘烤、震动等 | E13: 使用单位
C14: 扫描信息错误 | D14: 扫描信息与实际信息要求不符 | E14: 使用单位
B15: 同盘作业 | C15: 同盘作业 | D15: 待作业与作业OK未明显区分或在一个托盘内部 | E15: 使用单位
B16: 数据完整性与诚信违规 | C16: 做假记录、假数据的 | D16: 实际未按要求执行，直接填写数据的。（如：点检、抽检记录类等） | E16: 使用单位
B17: 抽检不良 | C17: 抽检 | D17: 点胶和涂油量过多或过少（前提有样品参考），贴纸浮起/贴歪，螺丝浮起 | E17: 使用单位
B18: 未使用螺丝十点法 | C18: 未使用防呆法 | D18: 螺丝岗位未使用防呆法、单部品混放 | E18: 使用单位
B19: 对策失效 | C19: 对策无实施 | D19: 部分对策已经明确要求实施实际没有执行的。（标准书配布中） | E19: 使用单位
B20: 包材/物料未清洗 | C20: 包材物料未清洗 | D20: 包材不按要求清洗、物料要求清洗未清洗 | E20: 使用单位
A21: 状态标识类 | B21: 无状态标识 | C21: 无状态标识 | D21: 无状态标识流程卡，单独产品无状态标识，不同状态未区分放置 | E21: 使用单位
B22: 标识与实物不符 | C22: 标识与实物不符 | D22: 状态不明无标识、有标识但肉眼难辨认的、胶水管制标签内容与实物不符 | E22: 使用单位
B23: 工作区域无划分不合理或不全 | C23: 区域规划不合理 | D23: 如本工位不良区域设定在其他工位，无三定管理 | E23: 使用单位
B24: 不良品未使用红包材 | C24: 不良品未使用红色包材 | D24: NG品未使用红色包材 | E24: 使用单位
B25: 设备标识牌无/错误 | C25: 设备标识错误/无 | D25: 设备运转时与状态牌是否符合 | E25: 使用单位
A26: 点检类 | B26: 点检数据/位置/规格错误 | C26: 点检结果超要求 | D26: 点检日期、位置、规格、数据及判别错误、涂改等 | E26: 使用单位
B27: 机台未点检作业 | C27: 未点检 | D27: 生产检验设备未进行点检的、未配布点检表，机台参数变更记录无技术、品质签名确认 | E27: 使用单位
A28: 错漏混 | B28: 错漏混 | C28: 错 | D28: 加工错、用错、胶水使用错误 | E28: 使用单位
C29: 漏 | D29: 漏工程的、漏方向或漏动作、漏部件、漏数据报告。 | E29: 使用单位
C30: 混 | D30: 混放、混装的 | E30: 使用单位
A31: 5S类 | B31: 不符合无尘室管理 | C31: 无尘管控违规 | D31: 风淋门异常、FFU未开启 | E31: 使用单位
B32: 现场环境脏乱 | C32: 环境脏乱 | D32: 工作杂物、废料、废胶堆积，台面/地面污渍灰尘未定期清理 | E32: 使用单位
B33: 人员穿戴不合无尘要求 | C33: 无尘着装违规 | D33: 无尘衣破损、头发/手腕/口鼻外露，违规穿戴进入无尘车间 | E33: 使用单位
B34: 物料防尘管理不到位 | C34: 物料防尘缺失 | D34: 物料无防尘防护、外包装未拆包直接进入洁净区 | E34: 使用单位
B35: 环境&净化设备异常 | C35: 温湿度/设备异常 | D35: 车间温湿度超标、FFU故障、风淋系统异常等 | E35: 使用单位
A36: 首检类 | B36: 首检类 | C36: 首件/首工序不良 | D36: 首工序机能/外观不良/无首件记录 | E36: 使用单位
A37: 违反准入要求 | B37: 未通过考核上岗 | C37: 违反上岗准入 | D37: 上岗人员无上岗证，上岗证与岗位不符，持证上岗无对应岗前培训记录 | E37: 使用单位
B38: 对作业要求不理解 | C38: 上岗能力不达标 | D38: 未吃透SOP作业标准，盲目上岗，频繁出现非标准作业 | E38: 使用单位
A39: 样品管理类 | B39: 无参考样品 | C39: 无样品作业 | D39: 工位无对应参考样品，员工仅凭经验作业，无实物比对依据，样品未放本岗位 | E39: 使用单位
B40: 未签订样品卡 | C40: 缺少样品管控卡 | D40: 使用样品无样品卡管控 | E40: 使用单位
...

Sheet 抽检数据  
A1: 抽检 状况 | B1: 一群点胶 -抽检数 | C1: 一群点胶 -不良数 | D1: 一群点胶 -良品数 | E1: 二群点胶 -抽检数 | F1: 二群点胶 -不良数 | G1: 二群点胶 -良品数 | H1: 三群点胶 -抽检数 | I1: 三群点胶 -不良数 | J1: 三群点胶 -良品数 | K1: 四群点胶 -抽检数 | L1: 四群点胶 -不良数 | M1: 四群点胶 -良品数 | N1: 五群点胶 -抽检数 | O1: 五群点胶 -不良数 | P1: 五群点胶 -良品数 | Q1: 六群点胶 -抽检数 | R1: 六群点胶 -不良数 | S1: 六群点胶 -良品数 | T1: OIS上滚珠片点胶 - 抽检数 | U1: OIS上滚珠片点胶 - 不良数 | V1: OIS上滚珠片点胶 - 良品数 | W1: OIS下滚珠片点胶 - 抽检数 | X1: OIS下滚珠片点胶 - 不良数 | Y1: OIS下滚珠片点胶 - 良品数 | Z1: OIS线圈点胶 - 抽检数 | AA1: OIS线圈点胶 - 不良数 | AB1: OIS线圈点胶 - 良品数 | AC1: OIS驱动磁石点胶 - 抽检数 | AD1: OIS驱动磁石点胶 - 不良数 | AE1: OIS驱动磁石点胶 - 良品数 | AF1: OIS感应磁石点胶 - 抽检数 | AG1: OIS感应磁石点胶 - 不良数 | AH1: OIS感应磁石点胶 - 良品数 | AI1: AF吸附磁石点胶 - 抽检数 | AJ1: AF吸附磁石点胶 - 不良数 | AK1: AF吸附磁石点胶 - 良品数 | AL1: AF线圈点胶 - 抽检数 | AM1: AF线圈点胶 - 不良数 | AN1: AF线圈点胶 - 良品数 | AO1: AF贴纸 - 抽检数 | AP1: AF贴纸 - 不良数 | AQ1: AF贴纸 - 良品数 | AR1: AF橡胶垫点胶 - 抽检数 | AS1: AF橡胶垫点胶 - 不良数 | AT1: AF橡胶垫点胶 - 良品数 | AU1: OISFPC点胶 - 抽检数 | AV1: OISFPC点胶 - 不良数 | AW1: OISFPC点胶 - 良品数 | AX1: AF磁轭磁石点胶 - 抽检数 | AY1: AF磁轭磁石点胶 - 不良数 | AZ1: AF磁轭磁石点胶 - 良品数 | BA1: AF主副导轴涂油 - 抽检数 | BB1: AF主副导轴涂油 - 不良数 | BC1: AF主副导轴涂油 - 良品数 | BD1: AF外观全点胶 - 抽检数 | BE1: AF外观全点胶 - 不良数 | BF1: AF外观全点胶 - 良品数 | BG1: AF支架锁附 - 抽检数 | BH1: AF支架锁附 - 不良数 | BI1: AF支架锁附 - 良品数 | BJ1: AFFPC - 抽检数 | BK1: AFFPC - 不良数 | BL1: AFFPC - 良品数 | BM1: 光圈/三群组装 - 抽检数 | BN1: 光圈/三群组装 - 不良数 | BO1: 光圈/三群组装 - 良品数 | BP1: 六群调芯点胶 - 抽检数 | BQ1: 六群调芯点胶 - 不良数 | BR1: 六群调芯点胶 - 良品数 | BS1: 金属套筒点胶 - 抽检数 | BT1: 金属套筒点胶 - 不良数 | BU1: 金属套筒点胶 - 良品数 | BV1: 外观筒 - 抽检数 | BW1: 外观筒 - 不良数 | BX1: 外观筒 - 良品数 | BY1: 一群调心点胶 - 抽检数 | BZ1: 一群调心点胶 - 不良数 | CA1: 一群调心点胶 - 良品数 | CB1: 尾板锁附 - 抽检数 | CC1: 尾板锁附 - 不良数 | CD1: 尾板锁附 - 良品数 | CE1: 销钉组装 - 抽检数 | CF1: 销钉组装 - 不良数 | CG1: 销钉组装 - 良品数 | CH1: 弹片点胶 - 抽检数 | CI1: 弹片点胶 - 不良数 | CJ1: 弹片点胶 - 良品数 | CK1: 光机组件锁附 - 抽检数 | CL1: 光机组件锁附 - 不良数 | CM1: 光机组件锁附 - 良品数 | CN1: 驱动板锁附 - 抽检数 | CO1: 驱动板锁附 - 不良数 | CP1: 驱动板锁附 - 良品数 | CQ1: 黄杨固定框锁附 - 抽检数 | CR1: 黄杨固定框锁附 - 不良数 | CS1: 黄杨固定框锁附 - 良品数 | CT1: 激光检测-抽检数 | CU1: 激光检测-不良品 | CV1: 激光检测-良品数 | CW1: 遮丑件组立及装配-抽检数 | CX1: 遮丑件组立及装配-不良品 | CY1: 遮丑件组立及装配-良品数 | CZ1: S F R 三合一-抽检数 | DA1: S F R 三合一-不良品 | DB1: S F R 三合一-良品数 | DC1: 保护玻璃保压-抽检数 | DD1: 保护玻璃保压-不良品 | DE1: 保护玻璃保压-良品数 | DF1: 半成品外观检测-抽检数 | DG1: 半成品外观检测-不良品 | DH1: 半成品外观检测-良品数 | DI1: 性能检测标定闭环-抽检数 | DJ1: 性能检测标定闭环-不良品 | DK1: 性能检测标定闭环-良品数 | DL1: 黄杨模组组装-抽检数 | DM1: 黄杨模组组装-不良品 | DN1: 黄杨模组组装-良品数 | DO1: Z O O M标定-抽检数 | DP1: Z O O M标定-不良品 | DQ1: Z O O M标定-良品数 | DR1: 一群组立-抽检数 | DS1: 一群组立-不良品 | DT1: 一群组立-良品数 | DU1: 合体外观检查-抽检数 | DV1: 合体外观检查-不良品 | DW1: 合体外观检查-良品数 | DX1: 震动测试-抽检数 | DY1: 震动测试-不良品 | DZ1: 震动测试-良品数 | EA1: 一群固定框双面胶锁附-抽检数 | EB1: 一群固定框双面胶锁附-不良品 | EC1: 一群固定框双面胶锁附-良品数 | ED1: 三级筒组件-抽检数 | EE1: 三级筒组件-不良品 | EF1: 三级筒组件-良品数 | EG1: AF群组件六群组件-抽检数 | EH1: AF群组件六群组件-不良品 | EI1: AF群组件六群组件-良品数 | EJ1: Z O O M固件烧录-抽检数 | EK1: Z O O M固件烧录-不良品 | EL1: Z O O M固件烧录-良品数 | EM1: 齿轮组装-抽检数 | EN1: 齿轮组装-不良品 | EO1: 齿轮组装-良品数 | EP1: 光机与外观筒装配-抽检数 | EQ1: 光机与外观筒装配-不良品 | ER1: 光机与外观筒装配-良品数 | ES1: 光通量标定-抽检数 | ET1: 光通量标定-不良品 | EU1: 光通量标定-良品数 | EV1: 一群三颗螺帽点胶-抽检数 | EW1: 一群三颗螺帽点胶-不良品 | EX1: 一群三颗螺帽点胶-良品数 | EY1: 波前后外观检查-抽检数 | EZ1: 波前后外观检查-不良品 | FA1: 波前后外观检查-良品数 | FB1: 六群组装-抽检数 | FC1: 六群组装-不良品 | FD1: 六群组装-良品数 | FE1: S N码烧录-抽检数 | FF1: S N码烧录-不良品 | FG1: S N码烧录-良品数 | FH1: 暗影测试-抽检数 | FI1: 暗影测试-不良品 | FJ1: 暗影测试-良品数 | FK1: 光圈三群组装锁附-抽检数 | FL1: 光圈三群组装锁附-不良品 | FM1: 光圈三群组装锁附-良品数 | FN1: 防抖件作动检测-抽检数 | FO1: 防抖件作动检测-不良品 | FP1: 防抖件作动检测-良品数 | FQ1: A F群组组装-抽检数 | FR1: A F群组组装-不良品 | FS1: A F群组组装-良品数 | FT1: O T P烧录确认-抽检数 | FU1: O T P烧录确认-不良品 | FV1: O T P烧录确认-良品数 | FW1: 六群凸轮框点胶-抽检数 | FX1: 六群凸轮框点胶-不良品 | FY1: 六群凸轮框点胶-良品数 | FZ1: 173/178点胶-抽检数 | GA1: 173/178点胶-不良品 | GB1: 173/178点胶-良品数 | GC1: 合体总组-抽检数 | GD1: 合体总组-不良品 | GE1: 合体总组-良品数
A2: 46221 | B2: 16 | C2: 0 | D2: 16 | E2: 15 | F2: 0 | G2: 15 | H2: 14 | I2: 0 | J2: 14 | K2: 26 | L2: 0 | M2: 26 | N2: 24 | O2: 0 | P2: 24 | Q2: 16 | R2: 0 | S2: 16 | T2: 15 | U2: 0 | V2: 15 | W2: 14 | X2: 0 | Y2: 14 | Z2: 22 | AA2: 0 | AB2: 22 | AC2: 25 | AD2: 0 | AE2: 25 | AF2: 32 | AG2: 0 | AH2: 32 | AI2: － | AJ2: － | AK2: － | AL2: 14 | AM2: 0 | AN2: 14 | AO2: 15 | AP2: 0 | AQ2: 15 | AR2: 18 | AS2: 0 | AT2: 18 | AU2: 11 | AV2: 0 | AW2: 11 | AX2: 6 | AY2: 0 | AZ2: 6 | BA2: 15 | BB2: 0 | BC2: 15 | BD2: 25 | BE2: 0 | BF2: 25 | BG2: － | BH2: － | BI2: － | BJ2: － | BK2: － | BL2: － | BM2: － | BN2: － | BO2: － | BP2: － | BQ2: － | BR2: － | BS2: － | BT2: － | BU2: － | BV2: － | BW2: － | BX2: － | BY2: － | BZ2: － | CA2: － | CB2: 24 | CC2: 0 | CD2: 24 | CE2: 14 | CF2: 0 | CG2: 14 | CH2: 15 | CI2: 0 | CJ2: 15 | CK2: 18 | CL2: 0 | CM2: 18 | CN2: 11 | CO2: 0 | CP2: 11 | CQ2: 6 | CR2: 0 | CS2: 6 | CT2: 15 | CU2: 0 | CV2: 15 | CW2: 25 | CX2: 0 | CY2: 25 | CZ2: =13+15 -> 28 | DA2: 0 | DB2: 28 | DC2: － | DD2: － | DE2: － | DF2: － | DG2: － | DH2: － | DI2: － | DJ2: － | DK2: － | DL2: 5 | DM2: 0 | DN2: 5 | DO2: 14 | DP2: 0 | DQ2: 14 | DR2: 18 | DS2: 1 | DT2: 17 | DU2: 10 | DV2: 0 | DW2: 10 | DX2: 18 | DY2: 0 | DZ2: 18 | EA2: 5 | EB2: 0 | EC2: 5 | ED2: 15 | EE2: 0 | EF2: 15 | EG2: 18 | EH2: 0 | EI2: 18 | EJ2: － | EK2: － | EL2: － | EM2: － | EN2: － | EO2: － | EP2: － | EQ2: － | ER2: － | ES2: － | ET2: － | EU2: － | EV2: － | EW2: － | EX2: － | EY2: － | EZ2: － | FA2: － | FB2: － | FC2: － | FD2: － | FE2: － | FF2: － | FG2: － | FH2: － | FI2: － | FJ2: － | FK2: － | FL2: － | FM2: － | FN2: － | FO2: － | FP2: － | FQ2: － | FR2: － | FS2: － | FT2: － | FU2: － | FV2: － | FW2: － | FX2: － | FY2: － | FZ2: － | GA2: － | GB2: － | GC2: － | GD2: － | GE2: －
A3: 46223 | B3: 12 | C3: 0 | D3: 12 | E3: 25 | F3: 0 | G3: 25 | H3: 16 | I3: 0 | J3: 16 | K3: 12 | L3: 0 | M3: 12 | N3: 25 | O3: 0 | P3: 25 | Q3: 12 | R3: 0 | S3: 12 | T3: 12 | U3: 0 | V3: 12 | W3: 23 | X3: 0 | Y3: 23 | Z3: 12 | AA3: 0 | AB3: 12 | AC3: 24 | AD3: 0 | AE3: 24 | AF3: 36 | AG3: 0 | AH3: 36 | AI3: 12 | AJ3: 0 | AK3: 12 | AL3: 23 | AM3: 0 | AN3: 23 | AO3: 23 | AP3: 0 | AQ3: 23 | AR3: 23 | AS3: 0 | AT3: 23 | AU3: 36 | AV3: 0 | AW3: 36 | AX3: 12 | AY3: 0 | AZ3: 12 | BA3: 14 | BB3: 0 | BC3: 14 | BD3: 12 | BE3: 0 | BF3: 12 | BG3: 20 | BH3: 0 | BI3: 20 | BJ3: － | BK3: － | BL3: － | BM3: － | BN3: － | BO3: － | BP3: 12 | BQ3: 0 | BR3: 12 | BS3: 23 | BT3: 0 | BU3: 23 | BV3: 12 | BW3: 0 | BX3: 12 | BY3: 24 | BZ3: 0 | CA3: 24 | CB3: =12+16 -> 28 | CC3: 0 | CD3: 28 | CE3: 12 | CF3: 0 | CG3: 12 | CH3: － | CI3: － | CJ3: － | CK3: － | CL3: － | CM3: － | CN3: － | CO3: － | CP3: － | CQ3: =17+6+6 -> 29 | CR3: 0 | CS3: 29 | CT3: － | CU3: － | CV3: － | CW3: － | CX3: － | CY3: － | CZ3: =16+15 -> 31 | DA3: 0 | DB3: 31 | DC3: － | DD3: － | DE3: － | DF3: － | DG3: － | DH3: － | DI3: 24 | DJ3: 0 | DK3: 24 | DL3: － | DM3: － | DN3: － | DO3: =17+10+6 -> 33 | DP3: 6 | DQ3: =33-6 -> 27 | DR3: =7+3+4 -> 14 | DS3: 0 | DT3: 14 | DU3: =15+5 -> 20 | DV3: 0 | DW3: 20 | DX3: =4+6+9+8 -> 27 | DY3: 0 | DZ3: 27 | EA3: － | EB3: － | EC3: － | ED3: 41 | EE3: 0 | EF3: 41 | EG3: － | EH3: － | EI3: － | EJ3: 16 | EK3: 0 | EL3: 16 | EM3: － | EN3: － | EO3: － | EP3: =12+2+2 -> 16 | EQ3: 0 | ER3: 16 | EV3: － | EW3: － | EX3: － | EY3: － | EZ3: － | FA3: － | FB3: － | FC3: － | FD3: － | FE3: － | FF3: － | FG3: － | FH3: － | FI3: － | FJ3: － | FK3: － | FL3: － | FM3: － | FN3: － | FO3: － | FP3: － | FQ3: － | FR3: － | FS3: － | FT3: － | FU3: － | FV3: － | FW3: － | FX3: － | FY3: － | FZ3: － | GA3: － | GB3: － | GC3: － | GD3: － | GE3: －
A4: 46224 | B4: =16+15 -> 31 | C4: 0 | D4: 31 | E4: 35 | F4: 0 | G4: 35 | H4: 20 | I4: 0 | J4: 20 | K4: 12 | L4: 0 | M4: 12 | N4: 16 | O4: 0 | P4: 16 | Q4: 12 | R4: 0 | S4: 12 | T4: 16 | U4: 0 | V4: 16 | W4: =16+15 -> 31 | X4: 0 | Y4: 31 | Z4: 35 | AA4: 0 | AB4: 35 | AC4: 20 | AD4: 0 | AE4: 20 | AF4: 12 | AG4: 0 | AH4: 12 | AI4: 12 | AJ4: 0 | AK4: 12 | AL4: 20 | AM4: 0 | AN4: 20 | AO4: － | AP4: － | AQ4: － | AR4: － | AS4: － | AT4: － | AU4: － | AV4: － | AW4: － | AX4: － | AY4: － | AZ4: － | BA4: － | BB4: － | BC4: － | BD4: － | BE4: － | BF4: － | BG4: － | BH4: － | BI4: － | BJ4: 40 | BK4: 0 | BL4: 40 | BM4: － | BN4: － | BO4: － | BP4: － | BQ4: － | BR4: － | BS4: － | BT4: － | BU4: － | BV4: － | BW4: － | BX4: － | BY4: 2 | BZ4: 0 | CA4: 2 | CB4: 16 | CC4: 0 | CD4: 16 | CE4: 14 | CF4: 0 | CG4: 14 | CH4: 16 | CI4: 0 | CJ4: 16 | CK4: 18 | CL4: 0 | CM4: 18 | CN4: 11 | CO4: 0 | CP4: 11 | CQ4: 6 | CR4: 0 | CS4: 6 | CT4: 15 | CU4: 0 | CV4: 15 | CW4: 25 | CX4: 0 | CY4: 25 | CZ4: =6+12+12 -> 30 | DA4: 0 | DB4: 30 | DC4: － | DD4: － | DE4: － | DF4: － | DG4: － | DH4: － | DI4: 15 | DJ4: 0 | DK4: 15 | DL4: 6 | DM4: 0 | DN4: 6 | DO4: =10+5+16 -> 31 | DP4: 0 | DQ4: 31 | DR4: 13 | DS4: 0 | DT4: 13 | DU4: =6+15+12+14 -> 47 | DV4: 0 | DW4: 47 | DX4: =4+4+8 -> 16 | DY4: 0 | DZ4: 16 | EA4: － | EB4: － | EC4: － | ED4: =8+24 -> 32 | EE4: 0 | EF4: 32 | EG4: － | EH4: － | EI4: － | EJ4: =14+12+18+24 -> 68 | EK4: 0 | EL4: 68 | EM4: 2 | EN4: 0 | EO4: 2 | EP4: － | EQ4: － | ER4: － | ES4: =6+12+7 -> 25 | ET4: 0 | EU4: 25 | EV4: － | EW4: － | EX4: － | EY4: － | EZ4: － | FA4: － | FB4: － | FC4: － | FD4: － | FE4: － | FF4: － | FG4: － | FH4: － | FI4: － | FJ4: － | FK4: － | FL4: － | FM4: － | FN4: － | FO4: － | FP4: － | FQ4: － | FR4: － | FS4: － | FT4: － | FU4: － | FV4: － | FW4: － | FX4: － | FY4: － | FZ4: － | GA4: － | GB4: － | GC4: － | GD4: － | GE4: －
A5: 46225 | B5: 26 | C5: 0 | D5: 26 | E5: － | F5: － | G5: － | H5: － | I5: － | J5: － | K5: 26 | L5: 0 | M5: 26 | N5: － | O5: － | P5: － | Q5: － | R5: － | S5: － | T5: － | U5: 0 | V5: － | W5: 26 | X5: 0 | Y5: 26 | Z5: － | AA5: － | AB5: － | AC5: － | AD5: － | AE5: － | AF5: 26 | AG5: 0 | AH5: 26 | AI5: － | AJ5: － | AK5: － | AL5: － | AM5: － | AN5: － | AO5: 40 | AP5: 0 | AQ5: 40 | AR5: － | AS5: － | AT5: － | AU5: － | AV5: － | AW5: － | AX5: － | AY5: － | AZ5: － | BA5: － | BB5: － | BC5: － | BD5: 40 | BE5: 0 | BF5: 40 | BG5: － | BH5: － | BI5: － | BJ5: － | BK5: － | BL5: － | BM5: － | BN5: － | BO5: － | BP5: =7+4 -> 11 | BQ5: 0 | BR5: 11 | BS5: － | BT5: － | BU5: － | BV5: 12 | BW5: 1 | BX5: 11 | BY5: 7 | BZ5: 0 | CA5: 7 | CB5: － | CC5: － | CD5: － | CE5: － | CF5: － | CG5: － | CH5: － | CI5: － | CJ5: － | CK5: － | CL5: － | CM5: － | CN5: 12 | CO5: 0 | CP5: 12 | CQ5: 12 | CR5: 0 | CS5: 12 | CT5: 5 | CU5: 0 | CV5: 5 | CW5: =7+16 -> 23 | CX5: 0 | CY5: 23 | CZ5: 20 | DA5: 0 | DB5: 20 | DC5: 9 | DD5: 0 | DE5: 9 | DF5: － | DG5: － | DH5: － | DI5: 7 | DJ5: 0 | DK5: 7 | DL5: － | DM5: － | DN5: － | DO5: － | DP5: － | DQ5: － | DR5: － | DS5: － | DT5: － | DU5: 39 | DV5: 0 | DW5: 39 | DX5: =28+17 -> 45 | DY5: 1 | DZ5: 44 | EA5: － | EB5: － | EC5: － | ED5: － | EE5: － | EF5: － | EG5: － | EH5: － | EI5: － | EJ5: 8 | EK5: 0 | EL5: 8 | EM5: － | EN5: － | EO5: － | EP5: － | EQ5: － | ER5: － | ES5: 9 | ET5: 0 | EU5: 9 | EV5: － | EW5: － | EX5: － | EY5: － | EZ5: － | FA5: － | FB5: － | FC5: － | FD5: － | FE5: － | FF5: － | FG5: － | FH5: － | FI5: － | FJ5: － | FK5: － | FL5: － | FM5: － | FN5: － | FO5: － | FP5: － | FQ5: － | FR5: － | FS5: － | FT5: － | FU5: － | FV5: － | FW5: － | FX5: － | FY5: － | FZ5: － | GA5: － | GB5: － | GC5: － | GD5: － | GE5: －
A6: 46226 | B6: 13 | C6: 0 | D6: 13 | E6: 20 | F6: 0 | G6: 20 | H6: 15 | I6: 0 | J6: 15 | K6: 13 | L6: 0 | M6: 13 | N6: 26 | O6: 0 | P6: 26 | Q6: 12 | R6: 0 | S6: 12 | T6: 23 | U6: 0 | V6: 23 | W6: 13 | X6: 0 | Y6: 13 | Z6: 45 | AA6: 0 | AB6: 45 | AC6: － | AD6: － | AE6: － | AF6: － | AG6: － | AH6: － | AI6: 40 | AJ6: 0 | AK6: 40 | AL6: － | AM6: － | AN6: － | AO6: － | AP6: － | AQ6: － | AR6: － | AS6: － | AT6: － | AU6: － | AV6: － | AW6: － | AX6: 20 | AY6: 1 | AZ6: 19 | BA6: － | BB6: － | BC6: － | BD6: 26 | BE6: 0 | BF6: 26 | BG6: － | BH6: － | BI6: － | BJ6: － | BK6: － | BL6: － | BM6: － | BN6: － | BO6: － | BP6: =5+2+6+2 -> 15 | BQ6: 0 | BR6: 15 | BS6: － | BT6: － | BU6: － | BV6: 4 | BW6: 0 | BX6: 4 | BY6: 9 | BZ6: 0 | CA6: 9 | CB6: =11+10+6 -> 27 | CC6: 0 | CD6: 27 | CE6: － | CF6: － | CG6: － | CH6: － | CI6: － | CJ6: － | CK6: － | CL6: － | CM6: － | CN6: =6+3 -> 9 | CO6: 0 | CP6: 9 | CQ6: =16+2 -> 18 | CR6: 0 | CS6: 18 | CT6: － | CU6: － | CV6: － | CW6: 1 | CX6: 0 | CY6: 1 | CZ6: =21+3+15 -> 39 | DA6: 0 | DB6: 39 | DC6: － | DD6: － | DE6: － | DF6: － | DG6: － | DH6: － | DI6: =7+2+3 -> 12 | DJ6: 0 | DK6: 12 | DL6: － | DM6: － | DN6: － | DO6: =5+6+5 -> 16 | DP6: 0 | DQ6: 16 | DR6: 14 | DS6: 0 | DT6: 14 | DU6: =12+3 -> 15 | DV6: 0 | DW6: 15 | DX6: 17 | DY6: 0 | DZ6: 17 | EA6: － | EB6: － | EC6: － | ED6: － | EE6: － | EF6: － | EG6: － | EH6: － | EI6: － | EJ6: =22+8 -> 30 | EK6: 0 | EL6: 30 | EM6: 15 | EN6: 0 | EO6: 15 | EP6: － | EQ6: － | ER6: － | ES6: =17+7 -> 24 | ET6: 0 | EU6: 24 | EV6: － | EW6: － | EX6: － | EY6: － | EZ6: － | FA6: － | FB6: － | FC6: － | FD6: － | FE6: － | FF6: － | FG6: － | FH6: － | FI6: － | FJ6: － | FK6: － | FL6: － | FM6: － | FN6: － | FO6: － | FP6: － | FQ6: － | FR6: － | FS6: － | FT6: － | FU6: － | FV6: － | FW6: － | FX6: － | FY6: － | FZ6: － | GA6: － | GB6: － | GC6: － | GD6: － | GE6: －
A7: 46227 | B7: 26 | C7: 0 | D7: 26 | E7: 25 | F7: 0 | G7: 25 | H7: 25 | I7: 0 | J7: 25 | K7: 23 | L7: 0 | M7: 23 | N7: 12 | O7: 0 | P7: 12 | Q7: 13 | R7: 0 | S7: 13 | T7: 16 | U7: 0 | V7: 16 | W7: 7 | X7: 0 | Y7: 7 | Z7: 30 | AA7: 0 | AB7: 30 | AC7: 25 | AD7: 0 | AE7: 25 | AF7: 11 | AG7: 0 | AH7: 11 | AI7: 26 | AJ7: 0 | AK7: 26 | AL7: － | AM7: － | AN7: － | AO7: － | AP7: － | AQ7: － | AR7: 16 | AS7: 0 | AT7: 16 | AU7: － | AV7: － | AW7: － | AX7: － | AY7: － | AZ7: － | BA7: － | BB7: － | BC7: － | BD7: 13 | BE7: 0 | BF7: 13 | BG7: － | BH7: － | BI7: － | BJ7: 23 | BK7: 0 | BL7: 23 | BM7: － | BN7: － | BO7: － | BP7: =9+4 -> 13 | BQ7: 0 | BR7: 13 | BS7: － | BT7: － | BU7: － | BV7: － | BW7: － | BX7: － | BY7: － | BZ7: － | CA7: － | CB7: =5+6+6+13 -> 30 | CC7: 0 | CD7: 30 | CE7: － | CF7: － | CG7: － | CH7: － | CI7: － | CJ7: － | CK7: － | CL7: － | CM7: － | CN7: =6+9 -> 15 | CO7: 1 | CP7: 14 | CQ7: － | CR7: － | CS7: － | CT7: － | CU7: － | CV7: － | CW7: 11 | CX7: 0 | CY7: 11 | CZ7: =16+6 -> 22 | DA7: 0 | DB7: 22 | DC7: － | DD7: － | DE7: － | DF7: － | DG7: － | DH7: － | DI7: 9 | DJ7: 0 | DK7: 9 | DL7: － | DM7: － | DN7: － | DO7: =10+9 -> 19 | DP7: 0 | DQ7: 19 | DR7: － | DS7: － | DT7: － | DU7: =5+10+11 -> 26 | DV7: 0 | DW7: 26 | DX7: 32 | DY7: 0 | DZ7: 32 | EA7: － | EB7: － | EC7: － | ED7: =18+6 -> 24 | EE7: 0 | EF7: 24 | EG7: － | EH7: － | EI7: － | EJ7: =8+12 -> 20 | EK7: 0 | EL7: 20 | EM7: － | EN7: － | EO7: － | EP7: － | EQ7: － | ER7: － | ES7: 16 | ET7: 0 | EU7: 16 | EV7: － | EW7: － | EX7: － | EY7: － | EZ7: － | FA7: － | FB7: － | FC7: － | FD7: － | FE7: － | FF7: － | FG7: － | FH7: － | FI7: － | FJ7: － | FK7: － | FL7: － | FM7: － | FN7: － | FO7: － | FP7: － | FQ7: － | FR7: － | FS7: － | FT7: － | FU7: － | FV7: － | FW7: － | FX7: － | FY7: － | FZ7: － | GA7: － | GB7: － | GC7: － | GD7: － | GE7: －
A8: 46228 | B8: 12 | C8: 0 | D8: 12 | E8: 26 | F8: 0 | G8: 26 | H8: 36 | I8: 0 | J8: 36 | K8: 12 | L8: 0 | M8: 12 | N8: 30 | O8: 0 | P8: 30 | Q8: 16 | R8: 0 | S8: 16 | T8: 12 | U8: 0 | V8: 12 | W8: 10 | X8: 0 | Y8: 10 | Z8: 25 | AA8: 0 | AB8: 25 | AC8: 26 | AD8: 0 | AE8: 26 | AF8: 31 | AG8: 0 | AH8: 31 | AI8: 13 | AJ8: 0 | AK8: 13 | AL8: － | AM8: － | AN8: － | AO8: 23 | AP8: 0 | AQ8: 23 | AR8: 13 | AS8: 0 | AT8: 13 | AU8: 20 | AV8: 0 | AW8: 20 | AX8: 15 | AY8: 0 | AZ8: 15 | BA8: 22 | BB8: 0 | BC8: 22 | BD8: 26 | BE8: 0 | BF8: 26 | BG8: 36 | BH8: 0 | BI8: 36 | BJ8: =6+2 -> 8 | BK8: 0 | BL8: 8 | BM8: 15 | BN8: 0 | BO8: 15 | BP8: 16 | BQ8: 0 | BR8: 16 | BS8: 17 | BT8: 0 | BU8: 17 | BV8: 35 | BW8: 0 | BX8: 35 | BY8: 12 | BZ8: 0 | CA8: 12 | CB8: 18 | CC8: 0 | CD8: 18 | CE8: 22 | CF8: 0 | CG8: 22 | CH8: 12 | CI8: 0 | CJ8: 12 | CK8: 36 | CL8: 0 | CM8: 36 | CN8: 13 | CO8: 0 | CP8: 13 | CQ8: 18 | CR8: 0 | CS8: 18 | CT8: 12 | CU8: 0 | CV8: 12 | CW8: 8 | CX8: 0 | CY8: 8 | CZ8: 15 | DA8: 0 | DB8: 15 | DC8: 8 | DD8: 0 | DE8: 8 | DF8: 23 | DG8: 0 | DH8: 23 | DI8: － | DJ8: － | DK8: － | DL8: － | DM8: － | DN8: － | DO8: － | DP8: － | DQ8: － | DR8: 3 | DS8: 0 | DT8: 3 | DU8: 2 | DV8: 0 | DW8: 2 | DX8: 36 | DY8: 0 | DZ8: 36 | EA8: 2 | EB8: 0 | EC8: 2 | ED8: 6 | EE8: 0 | EF8: 6 | EG8: － | EH8: － | EI8: － | EJ8: － | EK8: － | EL8: － | EM8: =24+7 -> 31 | EN8: 0 | EO8: 31 | EP8: － | EQ8: － | ER8: － | ES8: － | ET8: － | EU8: － | EV8: － | EW8: － | EX8: － | EY8: － | EZ8: － | FA8: － | FB8: － | FC8: － | FD8: － | FE8: － | FF8: － | FG8: － | FH8: － | FI8: － | FJ8: － | FK8: － | FL8: － | FM8: － | FN8: － | FO8: － | FP8: － | FQ8: － | FR8: － | FS8: － | FT8: － | FU8: － | FV8: － | FW8: － | FX8: － | FY8: － | FZ8: － | GA8: － | GB8: － | GC8: － | GD8: － | GE8: －
A9: 46230 | B9: 12 | C9: 0 | D9: 12 | E9: 14 | F9: 0 | G9: 14 | H9: 10 | I9: 0 | J9: 10 | K9: 17 | L9: 0 | M9: 17 | N9: 25 | O9: 0 | P9: 25 | Q9: 9 | R9: 0 | S9: 9 | T9: 12 | U9: 0 | V9: 12 | W9: 16 | X9: 0 | Y9: 16 | Z9: 18 | AA9: 0 | AB9: 18 | AC9: 27 | AD9: 0 | AE9: 27 | AF9: 15 | AG9: 0 | AH9: 15 | AI9: 16 | AJ9: 0 | AK9: 16 | AL9: 12 | AM9: 0 | AN9: 12 | AO9: 25 | AP9: 0 | AQ9: 25 | AR9: 11 | AS9: 0 | AT9: 11 | AU9: 6 | AV9: 0 | AW9: 6 | AX9: 24 | AY9: 0 | AZ9: 24 | BA9: 28 | BB9: 0 | BC9: 28 | BD9: 20 | BE9: 0 | BF9: 20 | BG9: 18 | BH9: 0 | BI9: 18 | BJ9: 5 | BK9: 0 | BL9: 5 | BM9: =17+8 -> 25 | BN9: 0 | BO9: 25 | BP9: 11 | BQ9: 0 | BR9: 11 | BS9: 14 | BT9: 0 | BU9: 14 | BV9: 10 | BW9: 0 | BX9: 10 | BY9: 7 | BZ9: 0 | CA9: 7 | CB9: 16 | CC9: 0 | CD9: 16 | CE9: 25 | CF9: 0 | CG9: 25 | CH9: 25 | CI9: 0 | CJ9: 25 | CK9: 9 | CL9: 0 | CM9: 9 | CN9: =2+4 -> 6 | CO9: 0 | CP9: 6 | CQ9: 9 | CR9: 0 | CS9: 9 | CT9: 33 | CU9: 0 | CV9: 33 | CW9: 10 | CX9: 0 | CY9: 10 | CZ9: 15 | DA9: 0 | DB9: 15 | DC9: 28 | DD9: 0 | DE9: 28 | DF9: － | DG9: － | DH9: － | DI9: － | DJ9: － | DK9: － | DL9: － | DM9: － | DN9: － | DO9: 25 | DP9: 0 | DQ9: 25 | DR9: 20 | DS9: 0 | DT9: 20 | DU9: － | DV9: － | DW9: － | DX9: 55 | DY9: 0 | DZ9: 55 | EA9: － | EB9: － | EC9: － | ED9: 26 | EE9: 0 | EF9: 26 | EV9: － | EW9: － | EX9: － | EY9: － | EZ9: － | FA9: － | FB9: － | FC9: － | FD9: － | FE9: － | FF9: － | FG9: － | FH9: － | FI9: － | FJ9: － | FK9: － | FL9: － | FM9: － | FN9: － | FO9: － | FP9: － | FQ9: － | FR9: － | FS9: － | FT9: － | FU9: － | FV9: － | FW9: － | FX9: － | FY9: － | FZ9: － | GA9: － | GB9: － | GC9: － | GD9: － | GE9: －
A10: 46231 | B10: 26 | C10: 0 | D10: 26 | E10: 20 | F10: 0 | G10: 20 | H10: 13 | I10: 0 | J10: 13 | K10: 16 | L10: 0 | M10: 16 | N10: 26 | O10: 0 | P10: 26 | Q10: 12 | R10: 0 | S10: 12 | T10: 16 | U10: 0 | V10: 16 | W10: 26 | X10: 0 | Y10: 26 | Z10: 15 | AA10: 0 | AB10: 15 | AC10: 15 | AD10: 0 | AE10: 15 | AF10: 25 | AG10: 0 | AH10: 25 | AI10: 11 | AJ10: 0 | AK10: 11 | AL10: 6 | AM10: 0 | AN10: 6 | AO10: 25 | AP10: 0 | AQ10: 25 | AR10: 25 | AS10: 0 | AT10: 25 | AU10: 9 | AV10: 0 | AW10: 9 | AX10: 6 | AY10: 0 | AZ10: 6 | BA10: 9 | BB10: 0 | BC10: 9 | BD10: 12 | BE10: 0 | BF10: 12 | BG10: 16 | BH10: 0 | BI10: 16 | BJ10: － | BK10: － | BL10: － | BM10: － | BN10: － | BO10: － | BP10: =16+6 -> 22 | BQ10: 0 | BR10: 22 | BS10: － | BT10: － | BU10: － | BV10: － | BW10: － | BX10: － | BY10: 4 | BZ10: 1 | CA10: 3 | CB10: 16 | CC10: 0 | CD10: 16 | CE10: － | CF10: － | CG10: － | CH10: － | CI10: － | CJ10: － | CK10: － | CL10: － | CM10: － | CN10: 20 | CO10: 0 | CP10: 20 | CQ10: =2+1+7 -> 10 | CR10: 0 | CS10: 10 | CT10: 1 | CU10: 0 | CV10: 1 | CW10: 3 | CX10: 0 | CY10: 3 | CZ10: 7 | DA10: 0 | DB10: 7 | DC10: － | DD10: － | DE10: － | DF10: － | DG10: － | DH10: － | DI10: =6+24 -> 30 | DJ10: 0 | DK10: 30 | DL10: － | DM10: － | DN10: － | DO10: 11 | DP10: 0 | DQ10: 11 | DR10: 22 | DS10: 0 | DT10: 22 | DU10: 12 | DV10: 0 | DW10: 12 | DX10: － | DY10: － | DZ10: － | EA10: 12 | EB10: 0 | EC10: 12 | ED10: － | EE10: － | EF10: － | EG10: － | EH10: － | EI10: － | EJ10: 26 | EK10: 0 | EL10: 26 | EM10: 6 | EN10: 0 | EO10: 6 | EP10: 24 | EQ10: 0 | ER10: 24 | ES10: 2 | ET10: 0 | EU10: 2 | EV10: － | EW10: － | EX10: － | EY10: － | EZ10: － | FA10: － | FB10: － | FC10: － | FD10: － | FE10: － | FF10: － | FG10: － | FH10: － | FI10: － | FJ10: － | FK10: － | FL10: － | FM10: － | FN10: － | FO10: － | FP10: － | FQ10: － | FR10: － | FS10: － | FT10: － | FU10: － | FV10: － | FW10: － | FX10: － | FY10: － | FZ10: － | GA10: － | GB10: － | GC10: － | GD10: － | GE10: －
A11: 46232 | B11: 12 | C11: 0 | D11: 12 | E11: 16 | F11: 0 | G11: 16 | H11: 23 | I11: 0 | J11: 23 | K11: 12 | L11: 0 | M11: 12 | N11: 12 | O11: 0 | P11: 12 | Q11: 16 | R11: 0 | S11: 16 | T11: 23 | U11: 0 | V11: 23 | W11: 12 | X11: 0 | Y11: 12 | Z11: 14 | AA11: 0 | AB11: 14 | AC11: 15 | AD11: 0 | AE11: 15 | AF11: 18 | AG11: 0 | AH11: 18 | AI11: 11 | AJ11: 0 | AK11: 11 | AL11: 6 | AM11: 0 | AN11: 6 | AO11: 15 | AP11: 0 | AQ11: 15 | AR11: 25 | AS11: 0 | AT11: 25 | AU11: 11 | AV11: 0 | AW11: 11 | AX11: 11 | AY11: 0 | AZ11: 11 | BA11: － | BB11: － | BC11: － | BD11: 20 | BE11: 0 | BF11: 20 | BG11: － | BH11: － | BI11: － | BJ11: － | BK11: － | BL11: － | BM11: 34 | BN11: 0 | BO11: 34 | BP11: =3+2+7 -> 12 | BQ11: 0 | BR11: 12 | BS11: － | BT11: － | BU11: － | BV11: 22 | BW11: 0 | BX11: 22 | BY11: 30 | BZ11: 0 | CA11: 30 | CB11: 12 | CC11: 1 | CD11: 11 | CE11: － | CF11: － | CG11: － | CH11: － | CI11: － | CJ11: － | CK11: － | CL11: － | CM11: － | CN11: 22 | CO11: 0 | CP11: 22 | CQ11: 9 | CR11: 0 | CS11: 9 | CT11: － | CU11: － | CV11: － | CW11: － | CX11: － | CY11: － | CZ11: 6 | DA11: 0 | DB11: 6 | DC11: － | DD11: － | DE11: － | DF11: 40 | DG11: 0 | DH11: 40 | DI11: 2 | DJ11: 0 | DK11: 2 | DL11: － | DM11: － | DN11: － | DO11: 30 | DP11: 0 | DQ11: 30 | DR11: =15+12 -> 27 | DS11: 0 | DT11: 27 | DU11: 9 | DV11: 0 | DW11: 9 | DX11: 24 | DY11: 0 | DZ11: 24 | EA11: 9 | EB11: 0 | EC11: 9 | ED11: － | EE11: － | EF11: － | EG11: － | EH11: － | EI11: － | EJ11: 17 | EK11: 0 | EL11: 17 | EM11: 22 | EN11: 0 | EO11: 22 | EP11: =17+5 -> 22 | EQ11: 0 | ER11: 22 | ES11: 3 | ET11: 0 | EU11: 3 | EV11: 12 | EW11: 0 | EX11: 12 | EY11: 6 | EZ11: 0 | FA11: 6 | FB11: 8 | FC11: 0 | FD11: 8 | FE11: － | FF11: － | FG11: － | FH11: － | FI11: － | FJ11: － | FK11: － | FL11: － | FM11: － | FN11: － | FO11: － | FP11: － | FQ11: － | FR11: － | FS11: － | FT11: － | FU11: － | FV11: － | FW11: － | FX11: － | FY11: － | FZ11: － | GA11: － | GB11: － | GC11: － | GD11: － | GE11: －
A12: 46233 | B12: 25 | C12: 0 | D12: 25 | E12: 25 | F12: 0 | G12: 25 | H12: 9 | I12: 0 | J12: 9 | K12: =2+4 -> 6 | L12: 0 | M12: 6 | N12: 9 | O12: 0 | P12: 9 | Q12: =17+8 -> 25 | R12: 0 | S12: 25 | T12: 11 | U12: 0 | V12: 11 | W12: 14 | X12: 0 | Y12: 14 | Z12: 10 | AA12: 0 | AB12: 10 | AC12: 7 | AD12: 0 | AE12: 7 | AF12: 16 | AG12: 0 | AH12: 16 | AI12: 35 | AJ12: 0 | AK12: 35 | AL12: 23 | AM12: 0 | AN12: 23 | AO12: 16 | AP12: 0 | AQ12: 16 | AR12: 26 | AS12: 0 | AT12: 26 | AU12: 20 | AV12: 0 | AW12: 20 | AX12: 13 | AY12: 0 | AZ12: 13 | BA12: 16 | BB12: 0 | BC12: 16 | BD12: 26 | BE12: 0 | BF12: 26 | BG12: 16 | BH12: 0 | BI12: 16 | BJ12: 15 | BK12: 0 | BL12: 15 | BM12: 20 | BN12: 0 | BO12: 20 | BP12: 15 | BQ12: 0 | BR12: 15 | BS12: － | BT12: － | BU12: － | BV12: 7 | BW12: 0 | BX12: 7 | BY12: 15 | BZ12: 0 | CA12: 15 | CB12: =30+24+24 -> 78 | CC12: 0 | CD12: 78 | CE12: － | CF12: － | CG12: － | CH12: － | CI12: － | CJ12: － | CK12: － | CL12: － | CM12: － | CN12: － | CO12: － | CP12: － | CQ12: 4 | CR12: 0 | CS12: 4 | CT12: － | CU12: － | CV12: － | CW12: － | CX12: － | CY12: － | CZ12: 6 | DA12: 0 | DB12: 6 | DC12: 15 | DD12: 0 | DE12: 15 | DF12: － | DG12: － | DH12: － | DI12: 5 | DJ12: 0 | DK12: 5 | DL12: － | DM12: － | DN12: － | DO12: 36 | DP12: 0 | DQ12: 36 | DR12: =8+12 -> 20 | DS12: 0 | DT12: 20 | DU12: =16+10 -> 26 | DV12: 0 | DW12: 26 | DX12: 23 | DY12: 0 | DZ12: 23 | EA12: =13+9 -> 22 | EB12: 0 | EC12: 22 | ED12: 15 | EE12: 0 | EF12: 15 | EG12: － | EH12: － | EI12: － | EJ12: 9 | EK12: 0 | EL12: 9 | EM12: =8+10+8 -> 26 | EN12: 0 | EO12: 26 | EP12: － | EQ12: － | ER12: － | ES12: =19+17 -> 36 | ET12: 0 | EU12: 36 | EV12: － | EW12: － | EX12: － | EY12: 4 | EZ12: 0 | FA12: 4 | FB12: =9+15 -> 24 | FC12: 0 | FD12: 24 | FE12: =15+13 -> 28 | FF12: 0 | FG12: 28 | FH12: 3 | FI12: 0 | FJ12: 3 | FK12: － | FL12: － | FM12: － | FN12: － | FO12: － | FP12: － | FQ12: － | FR12: － | FS12: － | FT12: － | FU12: － | FV12: － | FW12: － | FX12: － | FY12: － | FZ12: － | GA12: － | GB12: － | GC12: － | GD12: － | GE12: －
A13: 46234 | B13: 19 | C13: 0 | D13: 19 | E13: 25 | F13: 0 | G13: 25 | H13: 41 | I13: 0 | J13: 41 | K13: 25 | L13: 0 | M13: 25 | N13: 16 | O13: 0 | P13: 16 | Q13: 18 | R13: 0 | S13: 18 | T13: 26 | U13: 0 | V13: 26 | W13: 13 | X13: 0 | Y13: 13 | Z13: 32 | AA13: 0 | AB13: 32 | AC13: 17 | AD13: 0 | AE13: 17 | AF13: 15 | AG13: 0 | AH13: 15 | AI13: 26 | AJ13: 0 | AK13: 26 | AL13: 19 | AM13: 0 | AN13: 19 | AO13: 22 | AP13: 0 | AQ13: 22 | AR13: 13 | AS13: 0 | AT13: 13 | AU13: 27 | AV13: 0 | AW13: 27 | AX13: 25 | AY13: 0 | AZ13: 25 | BA13: 17 | BB13: 0 | BC13: 17 | BD13: 13 | BE13: 0 | BF13: 13 | BG13: 23 | BH13: 0 | BI13: 23 | BJ13: － | BK13: － | BL13: － | BM13: 30 | BN13: 0 | BO13: 30 | BP13: 4 | BQ13: 0 | BR13: 4 | BS13: － | BT13: － | BU13: － | BV13: － | BW13: － | BX13: － | BY13: =24+14+2 -> 40 | BZ13: 0 | CA13: 40 | CB13: 3 | CC13: 0 | CD13: 3 | CE13: 12 | CF13: 0 | CG13: 12 | CH13: 24 | CI13: 0 | CJ13: 24 | CK13: =12+16 -> 28 | CL13: 0 | CM13: 28 | CN13: 12 | CO13: 0 | CP13: 12 | CQ13: 10 | CR13: 0 | CS13: 10 | CT13: － | CU13: － | CV13: － | CW13: 10 | CX13: 0 | CY13: 10 | CZ13: 14 | DA13: 0 | DB13: 14 | DC13: 8 | DD13: 0 | DE13: 8 | DF13: － | DG13: － | DH13: － | DI13: 13 | DJ13: 0 | DK13: 13 | DL13: － | DM13: － | DN13: － | DO13: =7+13 -> 20 | DP13: 0 | DQ13: 20 | DR13: － | DS13: － | DT13: － | DU13: － | DV13: － | DW13: － | DX13: 19 | DY13: 0 | DZ13: 19 | EA13: － | EB13: － | EC13: － | ED13: － | EE13: － | EF13: － | EG13: － | EH13: － | EI13: － | EJ13: 11 | EK13: 0 | EL13: 11 | EM13: 24 | EN13: 0 | EO13: 24 | EP13: － | EQ13: － | ER13: － | ES13: =22+3+18+14 -> 57 | ET13: 0 | EU13: 57 | EV13: － | EW13: － | EX13: － | EY13: － | EZ13: － | FA13: － | FB13: 24 | FC13: 0 | FD13: 24 | FE13: － | FF13: － | FG13: － | FH13: － | FI13: － | FJ13: － | FK13: － | FL13: － | FM13: － | FN13: － | FO13: － | FP13: － | FQ13: － | FR13: － | FS13: － | FT13: － | FU13: － | FV13: － | FW13: － | FX13: － | FY13: － | FZ13: － | GA13: － | GB13: － | GC13: － | GD13: － | GE13: －
A14: 46235 | B14: 16 | C14: 0 | D14: 16 | E14: 26 | F14: 0 | G14: 26 | H14: 20 | I14: 0 | J14: 20 | K14: 13 | L14: 0 | M14: 13 | N14: 16 | O14: 0 | P14: 16 | Q14: 26 | R14: 0 | S14: 26 | T14: 5 | U14: 0 | V14: 5 | W14: 12 | X14: 0 | Y14: 12 | Z14: 16 | AA14: 0 | AB14: 16 | AC14: 26 | AD14: 0 | AE14: 26 | AF14: 15 | AG14: 0 | AH14: 15 | AI14: 16 | AJ14: 0 | AK14: 16 | AL14: 18 | AM14: 0 | AN14: 18 | AO14: 23 | AP14: 0 | AQ14: 23 | AR14: 16 | AS14: 0 | AT14: 16 | AU14: 25 | AV14: 0 | AW14: 25 | AX14: 7 | AY14: 0 | AZ14: 7 | BA14: 12 | BB14: 0 | BC14: 12 | BD14: =24+16 -> 40 | BE14: 0 | BF14: 40 | BG14: =12+16 -> 28 | BH14: 0 | BI14: 28 | BJ14: 12 | BK14: 0 | BL14: 12 | BM14: =31+16+16 -> 63 | BN14: 0 | BO14: 63 | BP14: 35 | BQ14: 0 | BR14: 35 | BS14: 20 | BT14: 0 | BU14: 20 | BV14: 12 | BW14: 0 | BX14: 12 | BY14: 16 | BZ14: 0 | CA14: 16 | CB14: =31+6 -> 37 | CC14: 0 | CD14: 37 | CE14: 35 | CF14: 0 | CG14: 35 | CH14: 15 | CI14: 0 | CJ14: 15 | CK14: =12+3+22+20 -> 57 | CL14: 0 | CM14: 57 | CN14: 16 | CO14: 0 | CP14: 16 | CQ14: － | CR14: － | CS14: － | CT14: － | CU14: － | CV14: － | CW14: － | CX14: － | CY14: － | CZ14: － | DA14: － | DB14: － | DC14: － | DD14: － | DE14: － | DF14: － | DG14: － | DH14: － | DI14: － | DJ14: － | DK14: － | DL14: － | DM14: － | DN14: － | DO14: 12 | DP14: 0 | DQ14: 12 | DR14: =25+15+18 -> 58 | DS14: 0 | DT14: 58 | DU14: =12+17 -> 29 | DV14: 0 | DW14: 29 | DX14: 21 | DY14: 0 | DZ14: 21 | EA14: =5+9 -> 14 | EB14: 0 | EC14: 14 | ED14: 24 | EE14: 0 | EF14: 24 | EG14: － | EH14: － | EI14: － | EJ14: － | EK14: － | EL14: － | EM14: － | EN14: － | EO14: － | EP14: － | EQ14: － | ER14: － | ES14: － | ET14: － | EU14: － | EV14: － | EW14: － | EX14: － | EY14: － | EZ14: － | FA14: － | FB14: 40 | FC14: 0 | FD14: 40 | FE14: － | FF14: － | FG14: － | FH14: － | FI14: － | FJ14: － | FK14: － | FL14: － | FM14: － | FN14: － | FO14: － | FP14: － | FQ14: － | FR14: － | FS14: － | FT14: － | FU14: － | FV14: － | FW14: － | FX14: － | FY14: － | FZ14: － | GA14: － | GB14: － | GC14: － | GD14: － | GE14: －
A15: 46237 | B15: 26 | C15: 0 | D15: 26 | E15: 13 | F15: 0 | G15: 13 | H15: 15 | I15: 0 | J15: 15 | K15: 27 | L15: 0 | M15: 27 | N15: 16 | O15: 0 | P15: 16 | Q15: 19 | R15: 0 | S15: 19 | T15: 27 | U15: 0 | V15: 27 | W15: 18 | X15: 0 | Y15: 18 | Z15: 25 | AA15: 0 | AB15: 25 | AC15: 36 | AD15: 0 | AE15: 36 | AF15: 45 | AG15: 0 | AH15: 45 | AI15: 23 | AJ15: 0 | AK15: 23 | AL15: 21 | AM15: 0 | AN15: 21 | AO15: 23 | AP15: 0 | AQ15: 23 | AR15: 21 | AS15: 0 | AT15: 21 | AU15: 26 | AV15: 0 | AW15: 26 | AX15: 15 | AY15: 0 | AZ15: 15 | BA15: 36 | BB15: 0 | BC15: 36 | BD15: 26 | BE15: 0 | BF15: 26 | BG15: 36 | BH15: 0 | BI15: 36 | BJ15: 6 | BK15: 1 | BL15: 5 | BM15: 25 | BN15: 0 | BO15: 25 | BP15: 36 | BQ15: 0 | BR15: 36 | BS15: 25 | BT15: 0 | BU15: 25 | BV15: 19 | BW15: 0 | BX15: 19 | BY15: 25 | BZ15: 0 | CA15: 25 | CB15: 24 | CC15: 0 | CD15: 24 | CE15: 17 | CF15: 0 | CG15: 17 | CH15: 25 | CI15: 0 | CJ15: 25 | CK15: 36 | CL15: 0 | CM15: 36 | CN15: 12 | CO15: 0 | CP15: 12 | CQ15: 13 | CR15: 0 | CS15: 13 | CT15: 12 | CU15: 0 | CV15: 12 | CW15: 18 | CX15: 0 | CY15: 18 | CZ15: 23 | DA15: 0 | DB15: 23 | DC15: 12 | DD15: 0 | DE15: 12 | DF15: 13 | DG15: 0 | DH15: 13 | DI15: － | DJ15: － | DK15: － | DL15: － | DM15: － | DN15: － | DO15: 12 | DP15: 0 | DQ15: 12 | DR15: 25 | DS15: 0 | DT15: 25 | DU15: － | DV15: － | DW15: － | DX15: 30 | DY15: 0 | DZ15: 30 | EA15: － | EB15: － | EC15: － | ED15: － | EE15: － | EF15: － | EG15: － | EH15: － | EI15: － | EJ15: 28 | EK15: 0 | EL15: 28 | EM15: 8 | EN15: 0 | EO15: 8 | EP15: 12 | EQ15: 0 | ER15: 12 | ES15: 13 | ET15: 0 | EU15: 13 | EV15: － | EW15: － | EX15: － | EY15: － | EZ15: － | FA15: － | FB15: － | FC15: － | FD15: － | FE15: － | FF15: － | FG15: － | FH15: － | FI15: － | FJ15: － | FK15: － | FL15: － | FM15: － | FN15: － | FO15: － | FP15: － | FQ15: － | FR15: － | FS15: － | FT15: － | FU15: － | FV15: － | FW15: － | FX15: － | FY15: － | FZ15: － | GA15: － | GB15: － | GC15: － | GD15: － | GE15: －
A16: 46238 | B16: 26 | C16: 0 | D16: 26 | E16: 27 | F16: 0 | G16: 27 | H16: 14 | I16: 0 | J16: 14 | K16: 16 | L16: 0 | M16: 16 | N16: 23 | O16: 0 | P16: 23 | Q16: 18 | R16: 0 | S16: 18 | T16: 12 | U16: 0 | V16: 12 | W16: 13 | X16: 0 | Y16: 13 | Z16: 26 | AA16: 0 | AB16: 26 | AC16: 15 | AD16: 0 | AE16: 15 | AF16: 26 | AG16: 0 | AH16: 26 | AI16: 15 | AJ16: 0 | AK16: 15 | AL16: 14 | AM16: 0 | AN16: 14 | AO16: 13 | AP16: 0 | AQ16: 13 | AR16: 21 | AS16: 0 | AT16: 21 | AU16: 13 | AV16: 0 | AW16: 13 | AX16: 10 | AY16: 0 | AZ16: 10 | BA16: 16 | BB16: 0 | BC16: 16 | BD16: 32 | BE16: 0 | BF16: 32 | BG16: 23 | BH16: 0 | BI16: 23 | BJ16: 46 | BK16: 0 | BL16: 46 | BM16: 23 | BN16: 0 | BO16: 23 | BP16: =13+5 -> 18 | BQ16: 0 | BR16: 18 | BS16: 23 | BT16: 0 | BU16: 23 | BV16: =12+6+8 -> 26 | BW16: 0 | BX16: 26 | BY16: =20+11+4+2 -> 37 | BZ16: 0 | CA16: 37 | CB16: =16+30+6+15 -> 67 | CC16: 0 | CD16: 67 | CE16: － | CF16: － | CG16: － | CH16: － | CI16: － | CJ16: － | CK16: － | CL16: － | CM16: － | CN16: － | CO16: － | CP16: － | CQ16: － | CR16: － | CS16: － | CT16: － | CU16: － | CV16: － | CW16: =8+3 -> 11 | CX16: 0 | CY16: 11 | CZ16: 23 | DA16: 0 | DB16: 23 | DC16: 12 | DD16: 0 | DE16: 12 | DF16: － | DG16: － | DH16: － | DI16: 6 | DJ16: 0 | DK16: 6 | DL16: － | DM16: － | DN16: － | DO16: =18+30 -> 48 | DP16: 0 | DQ16: 48 | DR16: =13+6+15+8 -> 42 | DS16: 0 | DT16: 42 | DU16: 22 | DV16: 0 | DW16: 22 | DX16: 24 | DY16: 0 | DZ16: 24 | EA16: =10+5+18 -> 33 | EB16: 0 | EC16: 33 | ED16: 38 | EE16: 0 | EF16: 38 | EG16: =16+16 -> 32 | EH16: 0 | EI16: 32 | EJ16: =12+9 -> 21 | EK16: 0 | EL16: 21 | EM16: =8+11+16+8+16 -> 59 | EN16: 0 | EO16: 59 | EP16: =9+12 -> 21 | EQ16: 0 | ER16: 21 | ES16: =12+14 -> 26 | ET16: 0 | EU16: 26 | EV16: － | EW16: － | EX16: － | EY16: － | EZ16: － | FA16: － | FB16: =11+8+20 -> 39 | FC16: 0 | FD16: 39 | FE16: － | FF16: － | FG16: － | FH16: =15+6+9 -> 30 | FI16: 0 | FJ16: 30 | FK16: =16+16+13 -> 45 | FL16: 0 | FM16: 45 | FN16: 16 | FO16: 0 | FP16: 16 | FQ16: － | FR16: － | FS16: － | FT16: － | FU16: － | FV16: － | FW16: － | FX16: － | FY16: － | FZ16: － | GA16: － | GB16: － | GC16: － | GD16: － | GE16: －
A17: 46239 | B17: 13 | C17: 0 | D17: 13 | E17: 20 | F17: 0 | G17: 20 | H17: 12 | I17: 0 | J17: 12 | K17: 26 | L17: 0 | M17: 26 | N17: 23 | O17: 0 | P17: 23 | Q17: 17 | R17: 0 | S17: 17 | T17: 15 | U17: 0 | V17: 15 | W17: 23 | X17: 0 | Y17: 23 | Z17: 13 | AA17: 0 | AB17: 13 | AC17: 17 | AD17: 0 | AE17: 17 | AF17: 25 | AG17: 0 | AH17: 25 | AI17: 36 | AJ17: 0 | AK17: 36 | AL17: 15 | AM17: 0 | AN17: 15 | AO17: 26 | AP17: 0 | AQ17: 26 | AR17: 22 | AS17: 0 | AT17: 22 | AU17: 25 | AV17: 0 | AW17: 25 | AX17: 16 | AY17: 0 | AZ17: 16 | BA17: 25 | BB17: 0 | BC17: 25 | BD17: 16 | BE17: 0 | BF17: 16 | BG17: 16 | BH17: 0 | BI17: 16 | BJ17: 25 | BK17: 0 | BL17: 25 | BM17: 45 | BN17: 0 | BO17: 45 | BP17: 16 | BQ17: 0 | BR17: 16 | BS17: 13 | BT17: 0 | BU17: 13 | BV17: 24 | BW17: 0 | BX17: 24 | BY17: 4 | BZ17: 0 | CA17: 4 | CB17: =18+36 -> 54 | CC17: 0 | CD17: 54 | CE17: 19 | CF17: 0 | CG17: 19 | CH17: 15 | CI17: 0 | CJ17: 15 | CK17: 25 | CL17: 0 | CM17: 25 | CN17: 14 | CO17: 0 | CP17: 14 | CQ17: 13 | CR17: 0 | CS17: 13 | CT17: 12 | CU17: 0 | CV17: 12 | CW17: 5 | CX17: 0 | CY17: 5 | CZ17: 10 | DA17: 0 | DB17: 10 | DC17: 6 | DD17: 0 | DE17: 6 | DF17: － | DG17: － | DH17: － | DI17: 21 | DJ17: 0 | DK17: 21 | DL17: － | DM17: － | DN17: － | DO17: － | DP17: － | DQ17: － | DR17: 16 | DS17: 0 | DT17: 16 | DU17: =6+3 -> 9 | DV17: 0 | DW17: 9 | DX17: =21+3 -> 24 | DY17: 0 | DZ17: 24 | EA17: =13+24 -> 37 | EB17: 0 | EC17: 37 | ED17: 20 | EE17: 0 | EF17: 20 | EG17: － | EH17: － | EI17: － | EJ17: 18 | EK17: 0 | EL17: 18 | EM17: =24+38 -> 62 | EN17: 0 | EO17: 62 | EP17: － | EQ17: － | ER17: － | ES17: 4 | ET17: 0 | EU17: 4 | EV17: － | EW17: － | EX17: － | EY17: － | EZ17: － | FA17: － | FB17: =16+21 -> 37 | FC17: 0 | FD17: 37 | FE17: － | FF17: － | FG17: － | FH17: =30+18 -> 48 | FI17: 0 | FJ17: 48 | FK17: 16 | FL17: 0 | FM17: 16 | FN17: =13+8 -> 21 | FO17: 0 | FP17: 21 | FQ17: =16+16+9+10 -> 51 | FR17: 0 | FS17: 51 | FT17: 23 | FU17: 0 | FV17: 23 | FW17: － | FX17: － | FY17: － | FZ17: － | GA17: － | GB17: － | GC17: － | GD17: － | GE17: －
A18: 46240 | B18: 12 | C18: 0 | D18: 12 | E18: 15 | F18: 0 | G18: 15 | H18: 26 | I18: 0 | J18: 26 | K18: 18 | L18: 0 | M18: 18 | N18: 15 | O18: 0 | P18: 15 | Q18: 19 | R18: 0 | S18: 19 | T18: 26 | U18: 0 | V18: 26 | W18: 19 | X18: 0 | Y18: 19 | Z18: 13 | AA18: 0 | AB18: 13 | AC18: 21 | AD18: 0 | AE18: 21 | AF18: 25 | AG18: 0 | AH18: 25 | AI18: 16 | AJ18: 0 | AK18: 16 | AL18: 18 | AM18: 0 | AN18: 18 | AO18: 32 | AP18: 0 | AQ18: 32 | AR18: 25 | AS18: 0 | AT18: 25 | AU18: 35 | AV18: 0 | AW18: 35 | AX18: 18 | AY18: 0 | AZ18: 18 | BA18: 18 | BB18: 0 | BC18: 18 | BD18: 19 | BE18: 0 | BF18: 19 | BG18: 19 | BH18: 0 | BI18: 19 | BJ18: 17 | BK18: 0 | BL18: 17 | BM18: 16 | BN18: 0 | BO18: 16 | BP18: 12 | BQ18: 0 | BR18: 12 | BS18: 13 | BT18: 0 | BU18: 13 | BV18: 28 | BW18: 0 | BX18: 28 | BY18: 15 | BZ18: 0 | CA18: 15 | CB18: 16 | CC18: 0 | CD18: 16 | CE18: 25 | CF18: 0 | CG18: 25 | CH18: 19 | CI18: 0 | CJ18: 19 | CK18: 26 | CL18: 0 | CM18: 26 | CN18: 15 | CO18: 0 | CP18: 15 | CQ18: 4 | CR18: 0 | CS18: 4 | CT18: 3 | CU18: 0 | CV18: 3 | CW18: 18 | CX18: 0 | CY18: 18 | CZ18: 10 | DA18: 0 | DB18: 10 | DC18: 12 | DD18: 12 | DE18: － | DF18: － | DG18: － | DH18: － | DI18: 12 | DJ18: 0 | DK18: 12 | DL18: － | DM18: － | DN18: － | DO18: 12 | DP18: 0 | DQ18: 12 | DR18: － | DS18: － | DT18: － | DU18: 18 | DV18: 0 | DW18: 18 | DX18: =22+6 -> 28 | DY18: 0 | DZ18: 28 | EA18: =4+12+18 -> 34 | EB18: 0 | EC18: 34 | ED18: 16 | EE18: 0 | EF18: 16 | EG18: － | EH18: － | EI18: － | EJ18: 6 | EK18: 0 | EL18: 6 | EM18: 16 | EN18: 0 | EO18: 16 | EP18: 6 | EQ18: 0 | ER18: 6 | ES18: 6 | ET18: 0 | EU18: 6 | EV18: － | EW18: － | EX18: － | EY18: － | EZ18: － | FA18: － | FB18: 39 | FC18: 0 | FD18: 39 | FE18: － | FF18: － | FG18: － | FH18: =12+4 -> 16 | FI18: 0 | FJ18: 16 | FK18: 16 | FL18: 0 | FM18: 16 | FN18: － | FO18: － | FP18: － | FQ18: 16 | FR18: 0 | FS18: 16 | FT18: 4 | FU18: 0 | FV18: 4 | FW18: =12+12+24 -> 48 | FX18: 0 | FY18: 48 | FZ18: － | GA18: － | GB18: － | GC18: － | GD18: － | GE18: －
A19: 46241 | B19: 23 | C19: 0 | D19: 23 | E19: 23 | F19: 0 | G19: 23 | H19: 24 | I19: 0 | J19: 24 | K19: 15 | L19: 0 | M19: 15 | N19: 16 | O19: 0 | P19: 16 | Q19: 15 | R19: 0 | S19: 15 | T19: 16 | U19: 0 | V19: 16 | W19: 14 | X19: 0 | Y19: 14 | Z19: 15 | AA19: 0 | AB19: 15 | AC19: 16 | AD19: 0 | AE19: 16 | AF19: 15 | AG19: 0 | AH19: 15 | AI19: 16 | AJ19: 0 | AK19: 16 | AL19: 26 | AM19: 0 | AN19: 26 | AO19: 36 | AP19: 0 | AQ19: 36 | AR19: 12 | AS19: 0 | AT19: 12 | AU19: 30 | AV19: 0 | AW19: 30 | AX19: 16 | AY19: 0 | AZ19: 16 | BA19: 12 | BB19: 0 | BC19: 12 | BD19: 10 | BE19: 0 | BF19: 10 | BG19: 25 | BH19: 0 | BI19: 25 | BJ19: 14 | BK19: 0 | BL19: 14 | BM19: 15 | BN19: 0 | BO19: 15 | BP19: 18 | BQ19: 0 | BR19: 18 | BS19: 11 | BT19: 0 | BU19: 11 | BV19: =7+12 -> 19 | BW19: 0 | BX19: 19 | BY19: 23 | BZ19: 0 | CA19: 23 | CB19: 45 | CC19: 0 | CD19: 45 | CE19: 26 | CF19: 0 | CG19: 26 | CH19: 36 | CI19: 0 | CJ19: 36 | CK19: 22 | CL19: 0 | CM19: 22 | CN19: 9 | CO19: 0 | CP19: 9 | CQ19: 6 | CR19: 0 | CS19: 6 | CT19: 14 | CU19: 0 | CV19: 14 | CW19: 18 | CX19: 0 | CY19: 18 | CZ19: 18 | DA19: 0 | DB19: 18 | DC19: 24 | DD19: 0 | DE19: 24 | DF19: 14 | DG19: 0 | DH19: 14 | DI19: 15 | DJ19: 0 | DK19: 15 | DL19: 12 | DM19: 0 | DN19: 12 | DO19: 12 | DP19: 0 | DQ19: 12 | DR19: =13+6+15+8 -> 42 | DS19: 0 | DT19: 42 | DU19: =16+10 -> 26 | DV19: 0 | DW19: 26 | DX19: 9 | DY19: 0 | DZ19: 9 | EA19: =20+16 -> 36 | EB19: 0 | EC19: 36 | ED19: 38 | EE19: 0 | EF19: 38 | EG19: 16 | EH19: 0 | EI19: 16 | EJ19: 15 | EK19: 0 | EL19: 15 | EM19: =8+16 -> 24 | EN19: 0 | EO19: 24 | EP19: 9 | EQ19: 0 | ER19: 9 | ES19: 6 | ET19: 0 | EU19: 6 | EV19: 12 | EW19: 0 | EX19: 12 | EY19: =4+24 -> 28 | EZ19: 0 | FA19: 28 | FB19: =4+24 -> 28 | FC19: 0 | FD19: 28 | FE19: － | FF19: － | FG19: － | FH19: － | FI19: － | FJ19: 16 | FK19: 0 | FL19: 16 | FM19: － | FN19: 16 | FO19: 0 | FP19: 16 | FQ19: 16 | FR19: 0 | FS19: 16 | FT19: － | FU19: － | FV19: － | FW19: =12+24 -> 36 | FX19: 0 | FY19: 36 | FZ19: － | GA19: － | GB19: － | GC19: － | GD19: － | GE19: －
A20: 46242 | B20: 13 | C20: 0 | D20: 13 | E20: 20 | F20: 0 | G20: 20 | H20: 15 | I20: 0 | J20: 15 | K20: 22 | L20: 0 | M20: 22 | N20: 16 | O20: 0 | P20: 16 | Q20: 26 | R20: 0 | S20: 26 | T20: 15 | U20: 0 | V20: 15 | W20: 26 | X20: 0 | Y20: 26 | Z20: 15 | AA20: 0 | AB20: 15 | AC20: 14 | AD20: 0 | AE20: 14 | AF20: 26 | AG20: 0 | AH20: 26 | AI20: 15 | AJ20: 0 | AK20: 15 | AL20: 15 | AM20: 0 | AN20: 15 | AO20: 25 | AP20: 0 | AQ20: 25 | AR20: 21 | AS20: 0 | AT20: 21 | AU20: 13 | AV20: 0 | AW20: 13 | AX20: 17 | AY20: 0 | AZ20: 17 | BA20: 15 | BB20: 0 | BC20: 15 | BD20: 36 | BE20: 0 | BF20: 36 | BG20: =6+2 -> 8 | BH20: 0 | BI20: 8 | BJ20: 15 | BK20: 0 | BL20: 15 | BM20: 16 | BN20: 0 | BO20: 16 | BP20: 17 | BQ20: 0 | BR20: 17 | BS20: 35 | BT20: 0 | BU20: 35 | BV20: 12 | BW20: 0 | BX20: 12 | BY20: 12 | BZ20: 0 | CA20: 12 | CB20: 18 | CC20: 0 | CD20: 18 | CE20: 22 | CF20: 0 | CG20: 22 | CH20: 12 | CI20: 0 | CJ20: 12 | CK20: 36 | CL20: 0 | CM20: 36 | CN20: 13 | CO20: 0 | CP20: 13 | CQ20: 24 | CR20: 0 | CS20: 24 | CT20: 28 | CU20: 0 | CV20: 28 | CW20: 20 | CX20: 0 | CY20: 20 | CZ20: 18 | DA20: 0 | DB20: 18 | DC20: 15 | DD20: 0 | DE20: 15 | DF20: 15 | DG20: 0 | DH20: 15 | DI20: 25 | DJ20: 0 | DK20: 25 | DL20: =6+12+12 -> 30 | DM20: 0 | DN20: 30 | DO20: =5+6+5 -> 16 | DP20: 0 | DQ20: 16 | DR20: 14 | DS20: 0 | DT20: 14 | DU20: =12+3 -> 15 | DV20: 0 | DW20: 15 | DX20: 17 | DY20: 0 | DZ20: 17 | EA20: 14 | EB20: 0 | EC20: 14 | ED20: 7 | EE20: 0 | EF20: 7 | EG20: 16 | EH20: 0 | EI20: 16 | EJ20: 15 | EK20: 0 | EL20: 15 | EM20: 21 | EN20: 0 | EO20: 21 | EP20: 23 | EQ20: 0 | ER20: 23 | ES20: － | ET20: － | EU20: － | EV20: － | EW20: － | EX20: － | EY20: 40 | EZ20: 0 | FA20: 40 | FB20: － | FC20: － | FD20: － | FE20: － | FF20: － | FG20: － | FH20: － | FI20: － | FJ20: － | FK20: － | FL20: － | FM20: － | FN20: 4 | FO20: 0 | FP20: 4 | FQ20: 20 | FR20: 0 | FS20: 20 | FT20: － | FU20: － | FV20: － | FW20: 24 | FX20: 0 | FY20: 24 | FZ20: － | GA20: － | GB20: － | GC20: － | GD20: － | GE20: －
A21: 46244 | B21: 7 | C21: 0 | D21: 7 | E21: 32 | F21: 0 | G21: 32 | H21: 15 | I21: 0 | J21: 15 | K21: 25 | L21: 0 | M21: 25 | N21: 14 | O21: 0 | P21: 14 | Q21: 18 | R21: 0 | S21: 18 | T21: 12 | U21: 0 | V21: 12 | W21: 45 | X21: 0 | Y21: 45 | Z21: 23 | AA21: 0 | AB21: 23 | AC21: 33 | AD21: 0 | AE21: 33 | AF21: 36 | AG21: 0 | AH21: 36 | AI21: 15 | AJ21: 0 | AK21: 15 | AL21: 16 | AM21: 0 | AN21: 16 | AO21: 45 | AP21: 0 | AQ21: 45 | AR21: 36 | AS21: 0 | AT21: 36 | AU21: 15 | AV21: 0 | AW21: 15 | AX21: 36 | AY21: 0 | AZ21: 36 | BA21: 24 | BB21: 0 | BC21: 24 | BD21: 16 | BE21: 0 | BF21: 16 | BG21: 52 | BH21: 0 | BI21: 52 | BJ21: 36 | BK21: 0 | BL21: 36 | BM21: 12 | BN21: 0 | BO21: 12 | BP21: 18 | BQ21: 0 | BR21: 18 | BS21: 19 | BT21: 0 | BU21: 19 | BV21: 40 | BW21: 0 | BX21: 40 | BY21: 36 | BZ21: 0 | CA21: 36 | CB21: 45 | CC21: 0 | CD21: 45 | CE21: 12 | CF21: 0 | CG21: 12 | CH21: 23 | CI21: 0 | CJ21: 23 | CK21: 52 | CL21: 0 | CM21: 52 | CN21: 14 | CO21: 0 | CP21: 14 | CQ21: 23 | CR21: 0 | CS21: 23 | CT21: 18 | CU21: 0 | CV21: 18 | CW21: 25 | CX21: 0 | CY21: 25 | CZ21: 12 | DA21: 0 | DB21: 12 | DC21: 18 | DD21: 0 | DE21: 18 | DF21: 22 | DG21: 0 | DH21: 22 | DI21: 12 | DJ21: 0 | DK21: 12 | DL21: 36 | DM21: 0 | DN21: 36 | DO21: 13 | DP21: 0 | DQ21: 13 | DR21: 15 | DS21: 0 | DT21: 15 | DU21: 21 | DV21: 0 | DW21: 21 | DX21: =5+9 -> 14 | DY21: 0 | DZ21: 14 | EA21: 24 | EB21: 0 | EC21: 24 | ED21: 15 | EE21: 0 | EF21: 15 | EG21: 13 | EH21: 0 | EI21: 13 | EJ21: 21 | EK21: 0 | EL21: 21 | EM21: 20 | EN21: 0 | EO21: 20 | EP21: － | EQ21: － | ER21: － | ES21: － | ET21: － | EU21: － | EV21: － | EW21: － | EX21: － | EY21: － | EZ21: － | FA21: － | FB21: － | FC21: － | FD21: － | FE21: － | FF21: － | FG21: － | FH21: － | FI21: － | FJ21: － | FK21: 42 | FL21: 0 | FM21: 42 | FN21: 10 | FO21: 0 | FP21: 10 | FQ21: － | FR21: － | FS21: － | FT21: － | FU21: － | FV21: － | FW21: 24 | FX21: 0 | FY21: 24 | FZ21: 15 | GA21: 0 | GB21: 15 | GC21: 19 | GD21: 0 | GE21: 19
A22: 46245 | B22: 12 | C22: 0 | D22: 12 | E22: 26 | F22: 0 | G22: 26 | H22: 16 | I22: 0 | J22: 16 | K22: 36 | L22: 0 | M22: 36 | N22: 15 | O22: 0 | P22: 15 | Q22: 16 | R22: 0 | S22: 16 | T22: 13 | U22: 0 | V22: 13 | W22: 14 | X22: 0 | Y22: 14 | Z22: 45 | AA22: 0 | AB22: 45 | AC22: 15 | AD22: 0 | AE22: 15 | AF22: 36 | AG22: 0 | AH22: 36 | AI22: 19 | AJ22: 0 | AK22: 19 | AL22: 16 | AM22: 0 | AN22: 16 | AO22: 71 | AP22: 0 | AQ22: 71 | AR22: 36 | AS22: 0 | AT22: 36 | AU22: 19 | AV22: 0 | AW22: 19 | AX22: 26 | AY22: 0 | AZ22: 26 | BA22: 36 | BB22: 0 | BC22: 36 | BD22: 18 | BE22: 0 | BF22: 18 | BG22: 36 | BH22: 0 | BI22: 36 | BJ22: 19 | BK22: 0 | BL22: 19 | BM22: 12 | BN22: 0 | BO22: 12 | BP22: 36 | BQ22: 0 | BR22: 36 | BS22: 16 | BT22: 0 | BU22: 16 | BV22: 26 | BW22: 0 | BX22: 26 | BY22: 45 | BZ22: 0 | CA22: 45 | CB22: 36 | CC22: 0 | CD22: 36 | CE22: 45 | CF22: 0 | CG22: 45 | CH22: 36 | CI22: 0 | CJ22: 36 | CK22: 26 | CL22: 0 | CM22: 26 | CN22: － | CO22: － | CP22: － | CQ22: － | CR22: － | CS22: － | CT22: － | CU22: － | CV22: － | CW22: － | CX22: － | CY22: － | CZ22: － | DA22: － | DB22: － | DC22: － | DD22: － | DE22: － | DF22: － | DG22: － | DH22: － | DI22: － | DJ22: － | DK22: － | DL22: － | DM22: － | DN22: － | DO22: － | DP22: － | DQ22: － | DR22: － | DS22: － | DT22: － | DU22: － | DV22: － | DW22: － | DX22: 6 | DY22: 0 | DZ22: 6 | EA22: 24 | EB22: 0 | EC22: 24 | ED22: 16 | EE22: 0 | EF22: 16 | EG22: 16 | EH22: 0 | EI22: 16 | EJ22: － | EK22: － | EL22: － | EM22: =16+16 -> 32 | EN22: 0 | EO22: 32 | EP22: =16+16 -> 32 | EQ22: 0 | ER22: 32 | ES22: － | ET22: － | EU22: － | EV22: － | EW22: － | EX22: － | EY22: － | EZ22: － | FA22: － | FB22: 16 | FC22: 0 | FD22: 16 | FE22: － | FF22: － | FG22: － | FH22: － | FI22: － | FJ22: － | FK22: － | FL22: － | FM22: － | FN22: 12 | FO22: 0 | FP22: 12 | FQ22: － | FR22: － | FS22: － | FT22: － | FU22: － | FV22: － | FW22: 12 | FX22: 0 | FY22: 12 | FZ22: － | GA22: － | GB22: － | GC22: － | GD22: － | GE22: －
A23: 46246 | B23: － | C23: － | D23: － | E23: － | F23: － | G23: － | H23: － | I23: － | J23: － | K23: － | L23: － | M23: － | N23: － | O23: － | P23: － | Q23: － | R23: － | S23: － | T23: － | U23: － | V23: － | W23: － | X23: － | Y23: － | Z23: － | AA23: － | AB23: － | AC23: － | AD23: － | AE23: － | AF23: － | AG23: － | AH23: － | AI23: － | AJ23: － | AK23: － | AL23: － | AM23: － | AN23: － | AO23: － | AP23: － | AQ23: － | AR23: － | AS23: － | AT23: － | AU23: － | AV23: － | AW23: － | AX23: － | AY23: － | AZ23: － | BA23: － | BB23: － | BC23: － | BD23: － | BE23: － | BF23: － | BG23: － | BH23: － | BI23: － | BJ23: － | BK23: － | BL23: － | BM23: － | BN23: － | BO23: － | BP23: =14+9+4 -> 27 | BQ23: 0 | BR23: 27 | BS23: － | BT23: － | BU23: － | BV23: － | BW23: － | BX23: － | BY23: 3 | BZ23: 0 | CA23: 3 | CB23: 28 | CC23: 0 | CD23: 28 | CE23: － | CF23: － | CG23: － | CH23: － | CI23: － | CJ23: － | CK23: － | CL23: － | CM23: － | CN23: 3 | CO23: 0 | CP23: 3 | CQ23: － | CR23: － | CS23: － | CT23: － | CU23: － | CV23: － | CW23: － | CX23: － | CY23: － | CZ23: － | DA23: － | DB23: － | DC23: － | DD23: － | DE23: － | DF23: － | DG23: － | DH23: － | DI23: 5 | DJ23: 0 | DK23: 5 | DL23: － | DM23: － | DN23: － | DO23: =7+6 -> 13 | DP23: 0 | DQ23: 13 | DR23: =18+12 -> 30 | DS23: 0 | DT23: 30 | DU23: － | DV23: － | DW23: － | DX23: 23 | DY23: 0 | DZ23: 23 | EA23: =20+16+12+17 -> 65 | EB23: 0 | EC23: 65 | ED23: =21+8 -> 29 | EE23: 0 | EF23: 29 | EG23: － | EH23: － | EI23: － | EJ23: 15 | EK23: 0 | EL23: 15 | EM23: =30+16+16 -> 62 | EN23: 0 | EO23: 62 | EP23: =18+23 -> 41 | EQ23: 0 | ER23: 41 | ES23: － | ET23: － | EU23: － | EV23: － | EW23: － | EX23: － | EY23: 12 | EZ23: 0 | FA23: 12 | FB23: 24 | FC23: 0 | FD23: 24 | FE23: － | FF23: － | FG23: － | FH23: － | FI23: － | FJ23: － | FK23: － | FL23: － | FM23: － | FN23: 14 | FO23: 0 | FP23: 14 | FQ23: 32 | FR23: 0 | FS23: 32 | FT23: － | FU23: － | FV23: － | FW23: =24+12+12+12 -> 60 | FX23: 0 | FY23: 60 | FZ23: － | GA23: － | GB23: － | GC23: － | GD23: － | GE23: －
A24: 46247 | B24: － | C24: － | D24: － | E24: － | F24: － | G24: － | H24: － | I24: － | J24: － | K24: － | L24: － | M24: － | N24: － | O24: － | P24: － | Q24: 15 | R24: 0 | S24: 15 | T24: － | U24: － | V24: － | W24: － | X24: － | Y24: － | Z24: － | AA24: － | AB24: － | AC24: － | AD24: － | AE24: － | AF24: － | AG24: － | AH24: － | AI24: － | AJ24: － | AK24: － | AL24: － | AM24: － | AN24: － | AO24: － | AP24: － | AQ24: － | AR24: － | AS24: － | AT24: － | AU24: － | AV24: － | AW24: － | AX24: － | AY24: － | AZ24: － | BA24: － | BB24: － | BC24: － | BD24: － | BE24: － | BF24: － | BG24: － | BH24: － | BI24: － | BJ24: － | BK24: － | BL24: － | BM24: － | BN24: － | BO24: － | BP24: － | BQ24: － | BR24: － | BS24: － | BT24: － | BU24: － | BV24: － | BW24: － | BX24: － | BY24: － | BZ24: － | CA24: － | CB24: － | CC24: － | CD24: － | CE24: － | CF24: － | CG24: － | CH24: － | CI24: － | CJ24: － | CK24: － | CL24: － | CM24: － | CN24: － | CO24: － | CP24: － | CQ24: 16 | CR24: 0 | CS24: 16 | CT24: － | CU24: － | CV24: － | CW24: － | CX24: － | CY24: － | CZ24: － | DA24: － | DB24: － | DC24: － | DD24: － | DE24: － | DF24: － | DG24: － | DH24: － | DI24: － | DJ24: － | DK24: － | DL24: － | DM24: － | DN24: － | DO24: － | DP24: － | DQ24: － | DR24: 9 | DS24: 0 | DT24: 9 | DU24: － | DV24: － | DW24: － | DX24: =12+4 -> 16 | DY24: 0 | DZ24: 16 | EA24: =18+17+5+12 -> 52 | EB24: 0 | EC24: 52 | ED24: =16+12 -> 28 | EE24: 0 | EF24: 28 | EG24: － | EH24: － | EI24: － | EJ24: － | EK24: － | EL24: － | EM24: =32+5 -> 37 | EN24: 0 | EO24: 37 | EP24: =24+6 -> 30 | EQ24: 0 | ER24: 30 | ES24: － | ET24: － | EU24: － | EV24: － | EW24: － | EX24: － | EY24: － | EZ24: － | FA24: － | FB24: 24 | FC24: 0 | FD24: 24 | FE24: － | FF24: － | FG24: － | FH24: － | FI24: － | FJ24: － | FK24: － | FL24: － | FM24: － | FN24: 6 | FO24: 0 | FP24: 6 | FQ24: =16+20+20 -> 56 | FR24: 0 | FS24: 56 | FT24: － | FU24: － | FV24: － | FW24: =24+12+12 -> 48 | FX24: 0 | FY24: 48 | FZ24: － | GA24: － | GB24: － | GC24: 17 | GD24: 0 | GE24: 17
A25: 46248 | B25: － | C25: － | D25: － | E25: － | F25: － | G25: － | H25: － | I25: － | J25: － | K25: － | L25: － | M25: － | N25: － | O25: － | P25: － | Q25: － | R25: － | S25: － | T25: － | U25: － | V25: － | W25: － | X25: － | Y25: － | Z25: － | AA25: － | AB25: － | AC25: － | AD25: － | AE25: － | AF25: － | AG25: － | AH25: － | AI25: － | AJ25: － | AK25: － | AL25: － | AM25: － | AN25: － | AO25: － | AP25: － | AQ25: － | AR25: － | AS25: － | AT25: － | AU25: － | AV25: － | AW25: － | AX25: － | AY25: － | AZ25: － | BA25: － | BB25: － | BC25: － | BD25: － | BE25: － | BF25: － | BG25: － | BH25: － | BI25: － | BJ25: － | BK25: － | BL25: － | BM25: － | BN25: － | BO25: － | BP25: 5 | BQ25: 0 | BR25: 5 | BS25: － | BT25: － | BU25: － | BV25: 10 | BW25: 0 | BX25: 10 | BY25: 23 | BZ25: 0 | CA25: 23 | CB25: － | CC25: － | CD25: － | CE25: － | CF25: － | CG25: － | CH25: － | CI25: － | CJ25: － | CK25: － | CL25: － | CM25: － | CN25: － | CO25: － | CP25: － | CQ25: － | CR25: － | CS25: － | CT25: － | CU25: － | CV25: － | CW25: － | CX25: － | CY25: － | CZ25: 21 | DA25: 0 | DB25: 21 | DC25: － | DD25: － | DE25: － | DF25: － | DG25: － | DH25: － | DI25: 12 | DJ25: 0 | DK25: 12 | DL25: 10 | DM25: 0 | DN25: 10 | DO25: 21 | DP25: 0 | DQ25: 21 | DR25: =18+3 -> 21 | DS25: 0 | DT25: 21 | DU25: － | DV25: － | DW25: － | DX25: 23 | DY25: 0 | DZ25: 23 | EA25: =30+36+12 -> 78 | EB25: 0 | EC25: 78 | ED25: =16+27 -> 43 | EE25: 0 | EF25: 43 | EG25: － | EH25: － | EI25: － | EJ25: 6 | EK25: 0 | EL25: 6 | EM25: =16+24 -> 40 | EN25: 0 | EO25: 40 | EP25: =36+36 -> 72 | EQ25: 0 | ER25: 72 | ES25: － | ET25: － | EU25: － | EV25: － | EW25: － | EX25: － | EY25: 25 | EZ25: 0 | FA25: 25 | FB25: 8 | FC25: 0 | FD25: 8 | FE25: － | FF25: － | FG25: － | FH25: － | FI25: － | FJ25: － | FK25: － | FL25: － | FM25: － | FN25: － | FO25: － | FP25: － | FQ25: =16+16 -> 32 | FR25: 0 | FS25: 32 | FT25: － | FU25: － | FV25: － | FW25: 24 | FX25: 0 | FY25: 24 | FZ25: － | GA25: － | GB25: － | GC25: － | GD25: － | GE25: －
A26: 46249 | B26: － | C26: － | D26: － | E26: － | F26: － | G26: － | H26: － | I26: － | J26: － | K26: － | L26: － | M26: － | N26: － | O26: － | P26: － | Q26: － | R26: － | S26: － | T26: － | U26: － | V26: － | W26: － | X26: － | Y26: － | Z26: － | AA26: － | AB26: － | AC26: － | AD26: － | AE26: － | AF26: － | AG26: － | AH26: － | AI26: － | AJ26: － | AK26: － | AL26: － | AM26: － | AN26: － | AO26: － | AP26: － | AQ26: － | AR26: － | AS26: － | AT26: － | AU26: － | AV26: － | AW26: － | AX26: － | AY26: － | AZ26: － | BA26: － | BB26: － | BC26: － | BD26: － | BE26: － | BF26: － | BG26: － | BH26: － | BI26: － | BJ26: － | BK26: － | BL26: － | BM26: － | BN26: － | BO26: － | BP26: =24+6+5 -> 35 | BQ26: 0 | BR26: 35 | BS26: － | BT26: － | BU26: － | BV26: 12 | BW26: 0 | BX26: 12 | BY26: － | BZ26: － | CA26: － | CB26: － | CC26: － | CD26: － | CE26: － | CF26: － | CG26: － | CH26: － | CI26: － | CJ26: － | CK26: － | CL26: － | CM26: － | CN26: =6+3 -> 9 | CO26: 0 | CP26: 9 | CQ26: =8+4+3 -> 15 | CR26: 0 | CS26: 15 | CT26: － | CU26: － | CV26: － | CW26: － | CX26: － | CY26: － | CZ26: =6+3 -> 9 | DA26: 0 | DB26: 9 | DC26: － | DD26: － | DE26: － | DF26: － | DG26: － | DH26: － | DI26: =6+16 -> 22 | DJ26: 0 | DK26: 22 | DL26: － | DM26: － | DN26: － | DO26: =6+8 -> 14 | DP26: 0 | DQ26: 14 | DR26: 10 | DS26: 0 | DT26: 10 | DU26: － | DV26: － | DW26: － | DX26: 18 | DY26: 0 | DZ26: 18 | EA26: =9+6 -> 15 | EB26: 0 | EC26: 15 | ED26: 32 | EE26: 0 | EF26: 32 | EG26: =23+8 -> 31 | EH26: 0 | EI26: 31 | EJ26: =24+4 -> 28 | EK26: 0 | EL26: 28 | EM26: =16+32 -> 48 | EN26: 0 | EO26: 48 | EP26: =12+12 -> 24 | EQ26: 0 | ER26: 24 | ES26: 5 | ET26: 0 | EU26: 5 | EV26: － | EW26: － | EX26: － | EY26: 12 | EZ26: 0 | FA26: 12 | FB26: 8 | FC26: 0 | FD26: 8 | FE26: － | FF26: － | FG26: － | FH26: － | FI26: － | FJ26: － | FK26: － | FL26: － | FM26: － | FN26: =16+16 -> 32 | FO26: 0 | FP26: 32 | FQ26: 10 | FR26: 0 | FS26: 10 | FT26: － | FU26: － | FV26: － | FW26: =38+24 -> 62 | FX26: 0 | FY26: 62 | FZ26: － | GA26: － | GB26: － | GC26: 16 | GD26: 0 | GE26: 16

Sheet 问题清单 
A1: 序号 | B1: 日期 | C1: 月份 | D1: 模块 | E1: 工位 | F1: 问题点描述 | G1: 类别 | H1: 分类 | I1: 人-张程亮 | J1: 机-陈刚 | K1: 料-王岩良 | L1: 法（QCP/SOP） | M1: 环境-刘焕良 | N1: 责任单位 | O1: 确认人 | P1: 工段负责人 | Q1: 巡检人 | R1: 是否结案 | S1: 逾期天数

Sheet 问题点-趋势图
C2: 责任单位 | D2: 类别 | E2: 7月 | F2: 8月 | G2: 46249 | H2: TTL | I2: Trend | K2: 5M | L2: 8/15问题件数 | O2: 未戴静电手环/未规范戴静电手环 | P2: 7
C3: 组立 | D3: 问题件数 | E3: =COUNTIFS('问题清单 '!$N$2:$N$135,"组立") -> 0 | F3: =COUNTIFS('问题清单 '!$N$136:$N$274,"组立") -> 0 | G3: =COUNTIFS('问题清单 '!$N$232:$N$261,"组立") -> 0 | H3: =SUM(E3:F3) -> 0 | K3: 人-张程亮 | L3: =COUNTIF('问题清单 '!$I$232:$I$261,"1") -> 0 | O3: FFU无飘带/防尘管理未到位/人员穿戴皮肤外露 | P3: 5
D4: 结案件数 | E4: =COUNTIFS('问题清单 '!$N$2:$N$135,"组立",'问题清单 '!$R$2:$R$135,"Close") -> 0 | F4: =COUNTIFS('问题清单 '!$N$136:$N$274,"组立",'问题清单 '!$R$136:$R$274,"Close") -> 0 | G4: =COUNTIFS('问题清单 '!$N$232:$N$261,"组立",'问题清单 '!$R$232:$R$261,"Close") -> 0 | H4: =SUM(E4:F4) -> 0 | K4: 机-陈刚 | L4: =COUNTIF('问题清单 '!$J$232:$J$261,"1") -> 0 | O4: 未点检/点检不在规格内/点检不规范 | P4: 4
D5: 结案率 | E5: =E4/E3 -> #DIV/0! | F5: =F4/F3 -> #DIV/0! | G5: =G4/G3 -> #DIV/0! | H5: =H4/H3 -> #DIV/0! | K5: 料-王岩良 | L5: =COUNTIF('问题清单 '!$K$232:$K$261,"1") -> 0 | O5: UV箱光积量未达到SOP要求/未使用十点法/未使用治具 | P5: 3
C6: 技术 | D6: 问题件数 | E6: =COUNTIFS('问题清单 '!$N$2:$N$135,"技术") -> 0 | F6: =COUNTIFS('问题清单 '!$N$136:$N$274,"技术") -> 0 | G6: =COUNTIFS('问题清单 '!$N$232:$N$261,"技术") -> 0 | H6: =SUM(E6:F6) -> 0 | K6: 法（QCP/SOP） | L6: =COUNTIF('问题清单 '!$L$232:$L$261,"1") -> 0 | O6: 电动起无封条/螺丝盘部番料号错误/新旧SOP共存 | P6: 3
D7: 结案件数 | E7: =COUNTIFS('问题清单 '!$N$2:$N$135,"技术",'问题清单 '!$R$2:$R$135,"Close") -> 0 | F7: =COUNTIFS('问题清单 '!$N$136:$N$274,"技术",'问题清单 '!$R$136:$R$274,"Close") -> 0 | G7: =COUNTIFS('问题清单 '!$N$232:$N$261,"技术",'问题清单 '!$R$232:$R$261,"Close") -> 0 | H7: =SUM(E7:F7) -> 0 | K7: 环-刘焕良 | L7: =COUNTIF('问题清单 '!$M$232:$M$261,"1") -> 0
D8: 结案率 | E8: =E7/E6 -> #DIV/0! | F8: =F7/F6 -> #DIV/0! | G8: =G7/G6 -> #DIV/0! | H8: =H7/H6 -> #DIV/0!
C9: 品质 | D9: 问题件数 | E9: =COUNTIFS('问题清单 '!$N$2:$N$135,"品质") -> 0 | F9: =COUNTIFS('问题清单 '!$N$136:$N$274,"品质") -> 0 | G9: =COUNTIFS('问题清单 '!$N$232:$N$261,"品质") -> 0 | H9: =SUM(E9:F9) -> 0 | L9: `
D10: 结案件数 | E10: =COUNTIFS('问题清单 '!$N$2:$N$135,"品质",'问题清单 '!$R$2:$R$135,"Close") -> 0 | F10: =COUNTIFS('问题清单 '!$N$136:$N$274,"品质",'问题清单 '!$R$136:$R$274,"Close") -> 0 | G10: =COUNTIFS('问题清单 '!$N$232:$N$261,"品质",'问题清单 '!$R$232:$R$261,"Close") -> 0 | H10: =SUM(E10:F10) -> 0 | O10: SOP标准缺失 | P10: 2
D11: 结案率 | E11: =E10/E9 -> #DIV/0! | F11: =F10/F9 -> #DIV/0! | G11: =G10/G9 -> #DIV/0! | H11: =H10/H9 -> #DIV/0! | O11: SOP内容错误 | P11: 4
C12: 运营 | D12: 问题件数 | E12: =COUNTIFS('问题清单 '!$N$2:$N$135,"运营") -> 0 | F12: =COUNTIFS('问题清单 '!$N$136:$N$274,"运营") -> 0 | G12: =COUNTIFS('问题清单 '!$N$232:$N$261,"运营") -> 0 | H12: =SUM(E12:F12) -> 0 | O12: SOP标准改动未配布 | P12: 1
D13: 结案件数 | E13: =COUNTIFS('问题清单 '!$N$2:$N$135,"运营",'问题清单 '!$R$2:$R$135,"Close") -> 0 | F13: =COUNTIFS('问题清单 '!$N$136:$N$274,"运营",'问题清单 '!$R$136:$R$274,"Close") -> 0 | G13: =COUNTIFS('问题清单 '!$N$232:$N$261,"运营",'问题清单 '!$R$232:$R$261,"Close") -> 0 | H13: =SUM(E13:F13) -> 0
D14: 结案率 | E14: =E13/E12 -> #DIV/0! | F14: =F13/F12 -> #DIV/0! | G14: =G13/G12 -> #DIV/0! | H14: =H13/H12 -> #DIV/0!
C15: 自动化 | D15: 问题件数 | E15: =COUNTIFS('问题清单 '!$N$2:$N$135,"自动化") -> 0 | F15: =COUNTIFS('问题清单 '!$N$136:$N$274,"自动化") -> 0 | G15: =COUNTIFS('问题清单 '!$N$232:$N$261,"自动化") -> 0 | H15: =SUM(E15:F15) -> 0
D16: 结案件数 | E16: =COUNTIFS('问题清单 '!$N$2:$N$135,"自动化",'问题清单 '!$R$2:$R$135,"Close") -> 0 | F16: =COUNTIFS('问题清单 '!$N$136:$N$274,"自动化",'问题清单 '!$R$136:$R$274,"Close") -> 0 | G16: =COUNTIFS('问题清单 '!$N$232:$N$261,"自动化",'问题清单 '!$R$232:$R$261,"Close") -> 0 | H16: =SUM(E16:F16) -> 0
D17: 结案率 | E17: =E16/E15 -> #DIV/0! | F17: =F16/F15 -> #DIV/0! | G17: =G16/G15 -> #DIV/0! | H17: =H16/H15 -> #DIV/0!
C19: ■ 问题类别
C20: 问题类别 | D20: 件数 | E20: 占比 | F20: close | G20: 结案率 | P20: 样品管理类
C21: 5S类 | D21: =COUNTIF('问题清单 '!$G$2:$G$7923,C21) -> 0 | E21: =D21/$D$34 -> #DIV/0! | F21: =COUNTIFS('问题清单 '!G:G,C21,'问题清单 '!R:R,"close") -> 0 | G21: =F21/D21 -> #DIV/0! | P21: 仪器管理类
C22: 标准书管理类 | D22: =COUNTIF('问题清单 '!$G$2:$G$7923,C22) -> 0 | E22: =D22/$D$34 -> #DIV/0! | F22: =COUNTIFS('问题清单 '!G:G,C22,'问题清单 '!R:R,"close") -> 0 | G22: =F22/D22 -> #DIV/0! | P22: 状态标识类
C23: 不按标准作业 | D23: =COUNTIF('问题清单 '!$G$2:$G$7923,C23) -> 0 | E23: =D23/$D$34 -> #DIV/0! | F23: =COUNTIFS('问题清单 '!G:G,C23,'问题清单 '!R:R,"close") -> 0 | G23: =F23/D23 -> #DIV/0!
C24: 错漏混 | D24: =COUNTIF('问题清单 '!$G$2:$G$7923,C24) -> 0 | E24: =D24/$D$34 -> #DIV/0! | F24: =COUNTIFS('问题清单 '!G:G,C24,'问题清单 '!R:R,"close") -> 0 | G24: =F24/D24 -> #DIV/0!
C25: 点检类 | D25: =COUNTIF('问题清单 '!$G$2:$G$7923,C25) -> 0 | E25: =D25/$D$34 -> #DIV/0! | F25: =COUNTIFS('问题清单 '!G:G,C25,'问题清单 '!R:R,"close") -> 0 | G25: =F25/D25 -> #DIV/0!
C26: 胶油管理类 | D26: =COUNTIF('问题清单 '!$G$2:$G$7923,C26) -> 0 | E26: =D26/$D$34 -> #DIV/0! | F26: =COUNTIFS('问题清单 '!G:G,C26,'问题清单 '!R:R,"close") -> 0 | G26: =F26/D26 -> #DIV/0!
C27: 静电管理类 | D27: =COUNTIF('问题清单 '!$G$2:$G$7923,C27) -> 0 | E27: =D27/$D$34 -> #DIV/0! | F27: =COUNTIFS('问题清单 '!G:G,C27,'问题清单 '!R:R,"close") -> 0 | G27: =F27/D27 -> #DIV/0!
C28: 首检不良 | D28: =COUNTIF('问题清单 '!$G$2:$G$7923,C28) -> 0 | E28: =D28/$D$34 -> #DIV/0! | F28: =COUNTIFS('问题清单 '!G:G,C28,'问题清单 '!R:R,"close") -> 0 | G28: =F28/D28 -> #DIV/0!
C29: 违反准入要求 | D29: =COUNTIF('问题清单 '!$G$2:$G$7923,C29) -> 0 | E29: =D29/$D$34 -> #DIV/0! | F29: =COUNTIFS('问题清单 '!G:G,C29,'问题清单 '!R:R,"close") -> 0 | G29: =F29/D29 -> #DIV/0!
C30: 样品管理类 | D30: =COUNTIF('问题清单 '!$G$2:$G$7923,C30) -> 0 | E30: =D30/$D$34 -> #DIV/0! | F30: =COUNTIFS('问题清单 '!G:G,C30,'问题清单 '!R:R,"close") -> 0 | G30: =F30/D30 -> #DIV/0!
C31: 仪器管理类 | D31: =COUNTIF('问题清单 '!$G$2:$G$7923,C31) -> 0 | E31: =D31/$D$34 -> #DIV/0! | F31: =COUNTIFS('问题清单 '!G:G,C31,'问题清单 '!R:R,"close") -> 0 | G31: =F31/D31 -> #DIV/0!
C32: 抽检类 | D32: =COUNTIF('问题清单 '!$G$2:$G$7923,C32) -> 0 | E32: =D32/$D$34 -> #DIV/0! | F32: =COUNTIFS('问题清单 '!G:G,C32,'问题清单 '!R:R,"close") -> 0 | G32: =F32/D32 -> #DIV/0!
